DEBUG:appServiceAppLogs:Waiting for the logs flag to be set
INFO:appsvc_profiler.installer:Code Profiler Installer is starting up
INFO:appsvc_profiler.installer:Cleaning up any existing status file which indicated signal handlers initialized status
INFO:appsvc_profiler.installer:Attempting to delete the signal_handler status file for instance id c20f4f091dde7fb92ca32c5e71f1247d15376f2b4b89c0dffe581e3d59c33c83
INFO:appsvc_profiler.installer:successfully deleted the status file
DEBUG:appsvc_profiler.installer:APPSETTING_WEBSITE_ENABLE_DEFAULT_CODE_PROFILER : None
INFO:appsvc_profiler.installer:Attempting to install the default code profiler.
DEBUG:appsvc_profiler.installer:viztracer would save traces to /tmp/c20f4f_profiler_trace.json
INFO:appsvc_profiler.installer:Successfully installed code profiler.
INFO:appsvc_profiler.installer:Signal Handlers SIGUSR for needed code-profiler have been initialized for gunicorn process on instance c20f4f091dde7fb92ca32c5e71f1247d15376f2b4b89c0dffe581e3d59c33c83
DEBUG:appsvc_profiler.installer:Code Profiler Installer is exiting as installation is completed
ERROR:cassandra.connection:Did not get expected SupportedMessage response; instead, got: <Error from server: code=000a [Protocol error] message="Invalid or unsupported protocol version 66">
WARNING:cassandra.cluster:[control connection] Error connecting to 74f3ea48-05df-4249-a12b-fac40645190d-us-east-1.db.astra.datastax.com:29042:0669df0f-031f-383e-b452-67a9679bbc6a:
Traceback (most recent call last):
  File "cassandra/cluster.py", line 3577, in cassandra.cluster.ControlConnection._reconnect_internal
  File "cassandra/cluster.py", line 3599, in cassandra.cluster.ControlConnection._try_connect
  File "cassandra/cluster.py", line 1670, in cassandra.cluster.Cluster.connection_factory
  File "cassandra/connection.py", line 855, in cassandra.connection.Connection.factory
cassandra.OperationTimedOut: errors=Timed out creating connection (5 seconds), last_host=None
WARNING:cassandra.cluster:Downgrading core protocol version from 66 to 65 for 74f3ea48-05df-4249-a12b-fac40645190d-us-east-1.db.astra.datastax.com:29042:98a2cd7e-fa1b-3950-942e-42af495c4248. To avoid this, it is best practice to explicitly set Cluster(protocol_version) to the version supported by your cluster. http://datastax.github.io/python-driver/api/cassandra/cluster.html#cassandra.cluster.Cluster.protocol_version
WARNING:cassandra.cluster:Downgrading core protocol version from 65 to 5 for 74f3ea48-05df-4249-a12b-fac40645190d-us-east-1.db.astra.datastax.com:29042:98a2cd7e-fa1b-3950-942e-42af495c4248. To avoid this, it is best practice to explicitly set Cluster(protocol_version) to the version supported by your cluster. http://datastax.github.io/python-driver/api/cassandra/cluster.html#cassandra.cluster.Cluster.protocol_version
WARNING:cassandra.cluster:Downgrading core protocol version from 5 to 4 for 74f3ea48-05df-4249-a12b-fac40645190d-us-east-1.db.astra.datastax.com:29042:98a2cd7e-fa1b-3950-942e-42af495c4248. To avoid this, it is best practice to explicitly set Cluster(protocol_version) to the version supported by your cluster. http://datastax.github.io/python-driver/api/cassandra/cluster.html#cassandra.cluster.Cluster.protocol_version
WARNING:cassandra.cluster:[control connection] Error connecting to 74f3ea48-05df-4249-a12b-fac40645190d-us-east-1.db.astra.datastax.com:29042:98a2cd7e-fa1b-3950-942e-42af495c4248:
Traceback (most recent call last):
  File "cassandra/cluster.py", line 3577, in cassandra.cluster.ControlConnection._reconnect_internal
  File "cassandra/cluster.py", line 3654, in cassandra.cluster.ControlConnection._try_connect
  File "cassandra/cluster.py", line 3635, in cassandra.cluster.ControlConnection._try_connect
  File "cassandra/connection.py", line 1126, in cassandra.connection.Connection.wait_for_responses
  File "cassandra/connection.py", line 1124, in cassandra.connection.Connection.wait_for_responses
  File "cassandra/connection.py", line 1636, in cassandra.connection.ResponseWaiter.deliver
cassandra.OperationTimedOut: errors=None, last_host=None
INFO:cassandra.policies:Using datacenter 'us-east-1' for DCAwareRoundRobinPolicy (via host '74f3ea48-05df-4249-a12b-fac40645190d-us-east-1.db.astra.datastax.com:29042:b4f6d9ed-0f1d-3f7a-82f1-a4a7ea4f84d4'); if incorrect, please specify a local_dc to the constructor, or limit contact points to local cluster nodes
WARNING:cassandra.cluster:[control connection] Error connecting to 74f3ea48-05df-4249-a12b-fac40645190d-us-east-1.db.astra.datastax.com:29042:b4f6d9ed-0f1d-3f7a-82f1-a4a7ea4f84d4:
Traceback (most recent call last):
  File "cassandra/cluster.py", line 3577, in cassandra.cluster.ControlConnection._reconnect_internal
  File "cassandra/cluster.py", line 3654, in cassandra.cluster.ControlConnection._try_connect
  File "cassandra/cluster.py", line 3651, in cassandra.cluster.ControlConnection._try_connect
  File "cassandra/cluster.py", line 3753, in cassandra.cluster.ControlConnection._refresh_schema
  File "cassandra/metadata.py", line 140, in cassandra.metadata.Metadata.refresh
  File "cassandra/metadata.py", line 163, in cassandra.metadata.Metadata._rebuild_all
  File "cassandra/metadata.py", line 2868, in get_all_keyspaces
  File "cassandra/metadata.py", line 2518, in get_all_keyspaces
  File "cassandra/metadata.py", line 2027, in get_all_keyspaces
  File "cassandra/metadata.py", line 2807, in cassandra.metadata.SchemaParserV4._query_all
  File "cassandra/connection.py", line 1126, in cassandra.connection.Connection.wait_for_responses
  File "cassandra/connection.py", line 1124, in cassandra.connection.Connection.wait_for_responses
  File "cassandra/connection.py", line 1636, in cassandra.connection.ResponseWaiter.deliver
cassandra.OperationTimedOut: errors=None, last_host=None
WARNING:cassandra.cluster:Found multiple hosts with the same endpoint (74f3ea48-05df-4249-a12b-fac40645190d-us-east-1.db.astra.datastax.com:29042:190dafab-6970-3a67-a21c-1226360de7dc). Excluding peer 10.0.0.1
INFO:cassandra.cluster:Cassandra host 74f3ea48-05df-4249-a12b-fac40645190d-us-east-1.db.astra.datastax.com:29042:b4f6d9ed-0f1d-3f7a-82f1-a4a7ea4f84d4 removed
WARNING:cassandra.cluster:Failed to create connection pool for new host 74f3ea48-05df-4249-a12b-fac40645190d-us-east-1.db.astra.datastax.com:29042:0750e59f-441b-37bb-b0a7-e097c5d725f7:
Traceback (most recent call last):
  File "cassandra/cluster.py", line 3234, in cassandra.cluster.Session.add_or_renew_pool.run_add_or_renew_pool
  File "cassandra/pool.py", line 406, in cassandra.pool.HostConnection.__init__
  File "cassandra/cluster.py", line 1670, in cassandra.cluster.Cluster.connection_factory
  File "cassandra/connection.py", line 855, in cassandra.connection.Connection.factory
cassandra.OperationTimedOut: errors=Timed out creating connection (5 seconds), last_host=None
WARNING:cassandra.cluster:Failed to create connection pool for new host 74f3ea48-05df-4249-a12b-fac40645190d-us-east-1.db.astra.datastax.com:29042:0669df0f-031f-383e-b452-67a9679bbc6a:
Traceback (most recent call last):
  File "cassandra/cluster.py", line 3234, in cassandra.cluster.Session.add_or_renew_pool.run_add_or_renew_pool
  File "cassandra/pool.py", line 406, in cassandra.pool.HostConnection.__init__
  File "cassandra/cluster.py", line 1670, in cassandra.cluster.Cluster.connection_factory
  File "cassandra/connection.py", line 855, in cassandra.connection.Connection.factory
cassandra.OperationTimedOut: errors=Timed out creating connection (5 seconds), last_host=None
WARNING:cassandra.cluster:Failed to create connection pool for new host 74f3ea48-05df-4249-a12b-fac40645190d-us-east-1.db.astra.datastax.com:29042:00958fd0-af98-391f-9f51-7e3fe763da5c:
Traceback (most recent call last):
  File "cassandra/cluster.py", line 3234, in cassandra.cluster.Session.add_or_renew_pool.run_add_or_renew_pool
  File "cassandra/pool.py", line 406, in cassandra.pool.HostConnection.__init__
  File "cassandra/cluster.py", line 1670, in cassandra.cluster.Cluster.connection_factory
  File "cassandra/connection.py", line 855, in cassandra.connection.Connection.factory
cassandra.OperationTimedOut: errors=Timed out creating connection (5 seconds), last_host=None
WARNING:cassandra.cluster:Failed to create connection pool for new host 74f3ea48-05df-4249-a12b-fac40645190d-us-east-1.db.astra.datastax.com:29042:00694036-11ec-39fb-8238-d79afd9b0e46:
Traceback (most recent call last):
  File "cassandra/cluster.py", line 3234, in cassandra.cluster.Session.add_or_renew_pool.run_add_or_renew_pool
  File "cassandra/pool.py", line 406, in cassandra.pool.HostConnection.__init__
  File "cassandra/cluster.py", line 1670, in cassandra.cluster.Cluster.connection_factory
  File "cassandra/connection.py", line 855, in cassandra.connection.Connection.factory
cassandra.OperationTimedOut: errors=Timed out creating connection (5 seconds), last_host=None
WARNING:cassandra.cluster:Failed to create connection pool for new host 74f3ea48-05df-4249-a12b-fac40645190d-us-east-1.db.astra.datastax.com:29042:98a2cd7e-fa1b-3950-942e-42af495c4248:
Traceback (most recent call last):
  File "cassandra/cluster.py", line 3234, in cassandra.cluster.Session.add_or_renew_pool.run_add_or_renew_pool
  File "cassandra/pool.py", line 406, in cassandra.pool.HostConnection.__init__
  File "cassandra/cluster.py", line 1670, in cassandra.cluster.Cluster.connection_factory
  File "cassandra/connection.py", line 855, in cassandra.connection.Connection.factory
cassandra.OperationTimedOut: errors=Timed out creating connection (5 seconds), last_host=None
INFO:app:*****************Prediction opening *************************
INFO:app:*****************Prediction opening *************************
INFO:app:*****************Prediction opening *************************
WARNING:cassandra.cluster:Downgrading core protocol version from 66 to 65 for 74f3ea48-05df-4249-a12b-fac40645190d-us-east-1.db.astra.datastax.com:29042:9e3a5bee-3d95-3bf7-90f5-09bd2177324b. To avoid this, it is best practice to explicitly set Cluster(protocol_version) to the version supported by your cluster. http://datastax.github.io/python-driver/api/cassandra/cluster.html#cassandra.cluster.Cluster.protocol_version
WARNING:cassandra.cluster:Downgrading core protocol version from 65 to 5 for 74f3ea48-05df-4249-a12b-fac40645190d-us-east-1.db.astra.datastax.com:29042:9e3a5bee-3d95-3bf7-90f5-09bd2177324b. To avoid this, it is best practice to explicitly set Cluster(protocol_version) to the version supported by your cluster. http://datastax.github.io/python-driver/api/cassandra/cluster.html#cassandra.cluster.Cluster.protocol_version
WARNING:cassandra.cluster:Downgrading core protocol version from 5 to 4 for 74f3ea48-05df-4249-a12b-fac40645190d-us-east-1.db.astra.datastax.com:29042:9e3a5bee-3d95-3bf7-90f5-09bd2177324b. To avoid this, it is best practice to explicitly set Cluster(protocol_version) to the version supported by your cluster. http://datastax.github.io/python-driver/api/cassandra/cluster.html#cassandra.cluster.Cluster.protocol_version
INFO:cassandra.policies:Using datacenter 'us-east-1' for DCAwareRoundRobinPolicy (via host '74f3ea48-05df-4249-a12b-fac40645190d-us-east-1.db.astra.datastax.com:29042:9e3a5bee-3d95-3bf7-90f5-09bd2177324b'); if incorrect, please specify a local_dc to the constructor, or limit contact points to local cluster nodes
WARNING:cassandra.cluster:Found multiple hosts with the same endpoint (74f3ea48-05df-4249-a12b-fac40645190d-us-east-1.db.astra.datastax.com:29042:9e3a5bee-3d95-3bf7-90f5-09bd2177324b). Excluding peer 10.0.0.6
INFO:cassandra.cluster:Cassandra host 74f3ea48-05df-4249-a12b-fac40645190d-us-east-1.db.astra.datastax.com:29042:00694036-11ec-39fb-8238-d79afd9b0e46 removed
INFO:app:*****************Prediction opening *************************
INFO:app:*****************Prediction for URL started *************************
INFO:app:time_response 0.179205
INFO:app:domain_spf 0
INFO:app:asn_ip 1
INFO:app:time_domain_activation 7070
INFO:app:time_domain_expiration 234
INFO:app:qty_ip_resolved 16
INFO:app:qty_nameservers None
INFO:app:qty_mx_servers None
INFO:app:ttl_hostname 1
INFO:app:tls_ssl_certificate 1
INFO:app:qty_redirects 0
INFO:app:url_google_index 0
INFO:app:domain_google_index 0
INFO:app:url_shortened 0
INFO:app:Domain: www.youtube.com
INFO:app:URL: https://www.youtube.com/results?search_query=speech+dataprocessing
INFO:app:*****************Prediction for https://www.youtube.com/results?search_query=speech+dataprocessing is Prediction says safe browsing URL *************************
WARNING:cassandra.cluster:Downgrading core protocol version from 66 to 65 for 74f3ea48-05df-4249-a12b-fac40645190d-us-east-1.db.astra.datastax.com:29042:00958fd0-af98-391f-9f51-7e3fe763da5c. To avoid this, it is best practice to explicitly set Cluster(protocol_version) to the version supported by your cluster. http://datastax.github.io/python-driver/api/cassandra/cluster.html#cassandra.cluster.Cluster.protocol_version
WARNING:cassandra.cluster:Downgrading core protocol version from 65 to 5 for 74f3ea48-05df-4249-a12b-fac40645190d-us-east-1.db.astra.datastax.com:29042:00958fd0-af98-391f-9f51-7e3fe763da5c. To avoid this, it is best practice to explicitly set Cluster(protocol_version) to the version supported by your cluster. http://datastax.github.io/python-driver/api/cassandra/cluster.html#cassandra.cluster.Cluster.protocol_version
WARNING:cassandra.cluster:Downgrading core protocol version from 5 to 4 for 74f3ea48-05df-4249-a12b-fac40645190d-us-east-1.db.astra.datastax.com:29042:00958fd0-af98-391f-9f51-7e3fe763da5c. To avoid this, it is best practice to explicitly set Cluster(protocol_version) to the version supported by your cluster. http://datastax.github.io/python-driver/api/cassandra/cluster.html#cassandra.cluster.Cluster.protocol_version
INFO:cassandra.policies:Using datacenter 'us-east-1' for DCAwareRoundRobinPolicy (via host '74f3ea48-05df-4249-a12b-fac40645190d-us-east-1.db.astra.datastax.com:29042:00958fd0-af98-391f-9f51-7e3fe763da5c'); if incorrect, please specify a local_dc to the constructor, or limit contact points to local cluster nodes
WARNING:cassandra.cluster:Found multiple hosts with the same endpoint (74f3ea48-05df-4249-a12b-fac40645190d-us-east-1.db.astra.datastax.com:29042:00958fd0-af98-391f-9f51-7e3fe763da5c). Excluding peer 10.0.0.7
INFO:cassandra.cluster:Cassandra host 74f3ea48-05df-4249-a12b-fac40645190d-us-east-1.db.astra.datastax.com:29042:00694036-11ec-39fb-8238-d79afd9b0e46 removed
WARNING:cassandra.cluster:[control connection] Error connecting to 74f3ea48-05df-4249-a12b-fac40645190d-us-east-1.db.astra.datastax.com:29042:00958fd0-af98-391f-9f51-7e3fe763da5c:
Traceback (most recent call last):
  File "cassandra/cluster.py", line 3577, in cassandra.cluster.ControlConnection._reconnect_internal
  File "cassandra/cluster.py", line 3654, in cassandra.cluster.ControlConnection._try_connect
  File "cassandra/cluster.py", line 3651, in cassandra.cluster.ControlConnection._try_connect
  File "cassandra/cluster.py", line 3753, in cassandra.cluster.ControlConnection._refresh_schema
  File "cassandra/metadata.py", line 140, in cassandra.metadata.Metadata.refresh
  File "cassandra/metadata.py", line 163, in cassandra.metadata.Metadata._rebuild_all
  File "cassandra/metadata.py", line 2868, in get_all_keyspaces
  File "cassandra/metadata.py", line 2518, in get_all_keyspaces
  File "cassandra/metadata.py", line 2027, in get_all_keyspaces
  File "cassandra/metadata.py", line 2807, in cassandra.metadata.SchemaParserV4._query_all
  File "cassandra/connection.py", line 1126, in cassandra.connection.Connection.wait_for_responses
  File "cassandra/connection.py", line 1124, in cassandra.connection.Connection.wait_for_responses
  File "cassandra/connection.py", line 1636, in cassandra.connection.ResponseWaiter.deliver
cassandra.OperationTimedOut: errors=None, last_host=None
INFO:cassandra.cluster:New Cassandra host <Host: 74f3ea48-05df-4249-a12b-fac40645190d-us-east-1.db.astra.datastax.com:29042:00694036-11ec-39fb-8238-d79afd9b0e46 us-east-1> discovered
WARNING:cassandra.cluster:Found multiple hosts with the same endpoint (74f3ea48-05df-4249-a12b-fac40645190d-us-east-1.db.astra.datastax.com:29042:678e6a1d-e5b1-3cba-b949-7bfaf823957f). Excluding peer 10.0.0.4
INFO:cassandra.cluster:Cassandra host 74f3ea48-05df-4249-a12b-fac40645190d-us-east-1.db.astra.datastax.com:29042:b4f6d9ed-0f1d-3f7a-82f1-a4a7ea4f84d4 removed
WARNING:cassandra.cluster:Downgrading core protocol version from 66 to 65 for 74f3ea48-05df-4249-a12b-fac40645190d-us-east-1.db.astra.datastax.com:29042:0750e59f-441b-37bb-b0a7-e097c5d725f7. To avoid this, it is best practice to explicitly set Cluster(protocol_version) to the version supported by your cluster. http://datastax.github.io/python-driver/api/cassandra/cluster.html#cassandra.cluster.Cluster.protocol_version
WARNING:cassandra.cluster:Downgrading core protocol version from 65 to 5 for 74f3ea48-05df-4249-a12b-fac40645190d-us-east-1.db.astra.datastax.com:29042:0750e59f-441b-37bb-b0a7-e097c5d725f7. To avoid this, it is best practice to explicitly set Cluster(protocol_version) to the version supported by your cluster. http://datastax.github.io/python-driver/api/cassandra/cluster.html#cassandra.cluster.Cluster.protocol_version
WARNING:cassandra.cluster:Downgrading core protocol version from 5 to 4 for 74f3ea48-05df-4249-a12b-fac40645190d-us-east-1.db.astra.datastax.com:29042:0750e59f-441b-37bb-b0a7-e097c5d725f7. To avoid this, it is best practice to explicitly set Cluster(protocol_version) to the version supported by your cluster. http://datastax.github.io/python-driver/api/cassandra/cluster.html#cassandra.cluster.Cluster.protocol_version
INFO:cassandra.policies:Using datacenter 'us-east-1' for DCAwareRoundRobinPolicy (via host '74f3ea48-05df-4249-a12b-fac40645190d-us-east-1.db.astra.datastax.com:29042:0750e59f-441b-37bb-b0a7-e097c5d725f7'); if incorrect, please specify a local_dc to the constructor, or limit contact points to local cluster nodes
WARNING:cassandra.cluster:Found multiple hosts with the same endpoint (74f3ea48-05df-4249-a12b-fac40645190d-us-east-1.db.astra.datastax.com:29042:0750e59f-441b-37bb-b0a7-e097c5d725f7). Excluding peer 10.0.0.8
INFO:cassandra.cluster:Cassandra host 74f3ea48-05df-4249-a12b-fac40645190d-us-east-1.db.astra.datastax.com:29042:00694036-11ec-39fb-8238-d79afd9b0e46 removed
INFO:app:*****************Prediction opening *************************
ERROR:app:Exception on /robots.txt [GET]
Traceback (most recent call last):
  File "/tmp/8dc9524939e911d/antenv/lib/python3.9/site-packages/urllib3/connectionpool.py", line 467, in _make_request
    self._validate_conn(conn)
  File "/tmp/8dc9524939e911d/antenv/lib/python3.9/site-packages/urllib3/connectionpool.py", line 1099, in _validate_conn
    conn.connect()
  File "/tmp/8dc9524939e911d/antenv/lib/python3.9/site-packages/urllib3/connection.py", line 653, in connect
    sock_and_verified = _ssl_wrap_socket_and_match_hostname(
  File "/tmp/8dc9524939e911d/antenv/lib/python3.9/site-packages/urllib3/connection.py", line 806, in _ssl_wrap_socket_and_match_hostname
    ssl_sock = ssl_wrap_socket(
  File "/tmp/8dc9524939e911d/antenv/lib/python3.9/site-packages/urllib3/util/ssl_.py", line 465, in ssl_wrap_socket
    ssl_sock = _ssl_wrap_socket_impl(sock, context, tls_in_tls, server_hostname)
  File "/tmp/8dc9524939e911d/antenv/lib/python3.9/site-packages/urllib3/util/ssl_.py", line 509, in _ssl_wrap_socket_impl
    return ssl_context.wrap_socket(sock, server_hostname=server_hostname)
  File "/opt/python/3.9.18/lib/python3.9/ssl.py", line 501, in wrap_socket
    return self.sslsocket_class._create(
  File "/opt/python/3.9.18/lib/python3.9/ssl.py", line 1074, in _create
    self.do_handshake()
  File "/opt/python/3.9.18/lib/python3.9/ssl.py", line 1343, in do_handshake
    self._sslobj.do_handshake()
ssl.SSLEOFError: EOF occurred in violation of protocol (_ssl.c:1129)

During handling of the above exception, another exception occurred:

Traceback (most recent call last):
  File "/tmp/8dc9524939e911d/antenv/lib/python3.9/site-packages/urllib3/connectionpool.py", line 793, in urlopen
    response = self._make_request(
  File "/tmp/8dc9524939e911d/antenv/lib/python3.9/site-packages/urllib3/connectionpool.py", line 491, in _make_request
    raise new_e
urllib3.exceptions.SSLError: EOF occurred in violation of protocol (_ssl.c:1129)

The above exception was the direct cause of the following exception:

Traceback (most recent call last):
  File "/tmp/8dc9524939e911d/antenv/lib/python3.9/site-packages/requests/adapters.py", line 486, in send
    resp = conn.urlopen(
  File "/tmp/8dc9524939e911d/antenv/lib/python3.9/site-packages/urllib3/connectionpool.py", line 847, in urlopen
    retries = retries.increment(
  File "/tmp/8dc9524939e911d/antenv/lib/python3.9/site-packages/urllib3/util/retry.py", line 515, in increment
    raise MaxRetryError(_pool, url, reason) from reason  # type: ignore[arg-type]
urllib3.exceptions.MaxRetryError: HTTPSConnectionPool(host='api.github.com', port=443): Max retries exceeded with url: /repos/rishabh11336/Log-Phishing-Detection/git/refs/heads/main (Caused by SSLError(SSLEOFError(8, 'EOF occurred in violation of protocol (_ssl.c:1129)')))

During handling of the above exception, another exception occurred:

Traceback (most recent call last):
  File "/tmp/8dc9524939e911d/antenv/lib/python3.9/site-packages/flask/app.py", line 1463, in wsgi_app
    response = self.full_dispatch_request()
  File "/tmp/8dc9524939e911d/antenv/lib/python3.9/site-packages/flask/app.py", line 873, in full_dispatch_request
    return self.finalize_request(rv)
  File "/tmp/8dc9524939e911d/antenv/lib/python3.9/site-packages/flask/app.py", line 894, in finalize_request
    response = self.process_response(response)
  File "/tmp/8dc9524939e911d/antenv/lib/python3.9/site-packages/flask/app.py", line 1271, in process_response
    response = self.ensure_sync(func)(response)
  File "/tmp/8dc9524939e911d/app.py", line 123, in after_request
    commit_to_github(commit_message=commit_message)
  File "/tmp/8dc9524939e911d/Logging/logcommit.py", line 93, in commit_to_github
    to_github(
  File "/tmp/8dc9524939e911d/Logging/logcommit.py", line 36, in to_github
    response = requests.get(url, headers=headers)
  File "/tmp/8dc9524939e911d/antenv/lib/python3.9/site-packages/requests/api.py", line 73, in get
    return request("get", url, params=params, **kwargs)
  File "/tmp/8dc9524939e911d/antenv/lib/python3.9/site-packages/requests/api.py", line 59, in request
    return session.request(method=method, url=url, **kwargs)
  File "/tmp/8dc9524939e911d/antenv/lib/python3.9/site-packages/requests/sessions.py", line 589, in request
    resp = self.send(prep, **send_kwargs)
  File "/tmp/8dc9524939e911d/antenv/lib/python3.9/site-packages/requests/sessions.py", line 703, in send
    r = adapter.send(request, **kwargs)
  File "/tmp/8dc9524939e911d/antenv/lib/python3.9/site-packages/requests/adapters.py", line 517, in send
    raise SSLError(e, request=request)
requests.exceptions.SSLError: HTTPSConnectionPool(host='api.github.com', port=443): Max retries exceeded with url: /repos/rishabh11336/Log-Phishing-Detection/git/refs/heads/main (Caused by SSLError(SSLEOFError(8, 'EOF occurred in violation of protocol (_ssl.c:1129)')))
ERROR:app:Exception on / [HEAD]
Traceback (most recent call last):
  File "/tmp/8dc9524939e911d/antenv/lib/python3.9/site-packages/flask/app.py", line 1463, in wsgi_app
    response = self.full_dispatch_request()
  File "/tmp/8dc9524939e911d/antenv/lib/python3.9/site-packages/flask/app.py", line 873, in full_dispatch_request
    return self.finalize_request(rv)
  File "/tmp/8dc9524939e911d/antenv/lib/python3.9/site-packages/flask/app.py", line 892, in finalize_request
    response = self.make_response(rv)
  File "/tmp/8dc9524939e911d/antenv/lib/python3.9/site-packages/flask/app.py", line 1164, in make_response
    raise TypeError(
TypeError: The view function for 'predictui' did not return a valid response. The function either returned None or ended without a return statement.
