DEBUG:appServiceAppLogs:Waiting for the logs flag to be set
INFO:appsvc_profiler.installer:Code Profiler Installer is starting up
INFO:appsvc_profiler.installer:Cleaning up any existing status file which indicated signal handlers initialized status
INFO:appsvc_profiler.installer:Attempting to delete the signal_handler status file for instance id 2b2b055676b587fdacdf457acb244ac221fe2733468695f0e94b714766eb40b6
INFO:appsvc_profiler.installer:successfully deleted the status file
DEBUG:appsvc_profiler.installer:APPSETTING_WEBSITE_ENABLE_DEFAULT_CODE_PROFILER : None
INFO:appsvc_profiler.installer:Attempting to install the default code profiler.
DEBUG:appsvc_profiler.installer:viztracer would save traces to /tmp/2b2b05_profiler_trace.json
INFO:appsvc_profiler.installer:Successfully installed code profiler.
INFO:appsvc_profiler.installer:Signal Handlers SIGUSR for needed code-profiler have been initialized for gunicorn process on instance 2b2b055676b587fdacdf457acb244ac221fe2733468695f0e94b714766eb40b6
DEBUG:appsvc_profiler.installer:Code Profiler Installer is exiting as installation is completed
INFO:app:*****************Prediction opening *************************
INFO:app:*****************Prediction opening *************************
INFO:app:*****************Prediction opening *************************
INFO:app:*****************Prediction opening *************************
INFO:app:*****************Prediction opening *************************
INFO:app:*****************Prediction opening *************************
ERROR:cassandra.datastax.cloud:<urlopen error [Errno -2] Name or service not known>
Traceback (most recent call last):
  File "/opt/python/3.9.21/lib/python3.9/urllib/request.py", line 1346, in do_open
    h.request(req.get_method(), req.selector, req.data, headers,
  File "/opt/python/3.9.21/lib/python3.9/http/client.py", line 1285, in request
    self._send_request(method, url, body, headers, encode_chunked)
  File "/opt/python/3.9.21/lib/python3.9/http/client.py", line 1331, in _send_request
    self.endheaders(body, encode_chunked=encode_chunked)
  File "/opt/python/3.9.21/lib/python3.9/http/client.py", line 1280, in endheaders
    self._send_output(message_body, encode_chunked=encode_chunked)
  File "/opt/python/3.9.21/lib/python3.9/http/client.py", line 1040, in _send_output
    self.send(msg)
  File "/opt/python/3.9.21/lib/python3.9/http/client.py", line 980, in send
    self.connect()
  File "/opt/python/3.9.21/lib/python3.9/http/client.py", line 1447, in connect
    super().connect()
  File "/opt/python/3.9.21/lib/python3.9/http/client.py", line 946, in connect
    self.sock = self._create_connection(
  File "/opt/python/3.9.21/lib/python3.9/socket.py", line 835, in create_connection
    for res in getaddrinfo(host, port, 0, SOCK_STREAM):
  File "/opt/python/3.9.21/lib/python3.9/socket.py", line 966, in getaddrinfo
    for res in _socket.getaddrinfo(host, port, family, type, proto, flags):
socket.gaierror: [Errno -2] Name or service not known

During handling of the above exception, another exception occurred:

Traceback (most recent call last):
  File "/tmp/8dc9524939e911d/antenv/lib/python3.9/site-packages/cassandra/datastax/cloud/__init__.py", line 137, in read_metadata_info
    response = urlopen(url, context=config.ssl_context, timeout=timeout)
  File "/opt/python/3.9.21/lib/python3.9/urllib/request.py", line 214, in urlopen
    return opener.open(url, data, timeout)
  File "/opt/python/3.9.21/lib/python3.9/urllib/request.py", line 517, in open
    response = self._open(req, data)
  File "/opt/python/3.9.21/lib/python3.9/urllib/request.py", line 534, in _open
    result = self._call_chain(self.handle_open, protocol, protocol +
  File "/opt/python/3.9.21/lib/python3.9/urllib/request.py", line 494, in _call_chain
    result = func(*args)
  File "/opt/python/3.9.21/lib/python3.9/urllib/request.py", line 1389, in https_open
    return self.do_open(http.client.HTTPSConnection, req,
  File "/opt/python/3.9.21/lib/python3.9/urllib/request.py", line 1349, in do_open
    raise URLError(err)
urllib.error.URLError: <urlopen error [Errno -2] Name or service not known>
ERROR:cassandra.datastax.cloud:<urlopen error [Errno -2] Name or service not known>
Traceback (most recent call last):
  File "/opt/python/3.9.21/lib/python3.9/urllib/request.py", line 1346, in do_open
    h.request(req.get_method(), req.selector, req.data, headers,
  File "/opt/python/3.9.21/lib/python3.9/http/client.py", line 1285, in request
    self._send_request(method, url, body, headers, encode_chunked)
  File "/opt/python/3.9.21/lib/python3.9/http/client.py", line 1331, in _send_request
    self.endheaders(body, encode_chunked=encode_chunked)
  File "/opt/python/3.9.21/lib/python3.9/http/client.py", line 1280, in endheaders
    self._send_output(message_body, encode_chunked=encode_chunked)
  File "/opt/python/3.9.21/lib/python3.9/http/client.py", line 1040, in _send_output
    self.send(msg)
  File "/opt/python/3.9.21/lib/python3.9/http/client.py", line 980, in send
    self.connect()
  File "/opt/python/3.9.21/lib/python3.9/http/client.py", line 1447, in connect
    super().connect()
  File "/opt/python/3.9.21/lib/python3.9/http/client.py", line 946, in connect
    self.sock = self._create_connection(
  File "/opt/python/3.9.21/lib/python3.9/socket.py", line 835, in create_connection
    for res in getaddrinfo(host, port, 0, SOCK_STREAM):
  File "/opt/python/3.9.21/lib/python3.9/socket.py", line 966, in getaddrinfo
    for res in _socket.getaddrinfo(host, port, family, type, proto, flags):
socket.gaierror: [Errno -2] Name or service not known

During handling of the above exception, another exception occurred:

Traceback (most recent call last):
  File "/tmp/8dc9524939e911d/antenv/lib/python3.9/site-packages/cassandra/datastax/cloud/__init__.py", line 137, in read_metadata_info
    response = urlopen(url, context=config.ssl_context, timeout=timeout)
  File "/opt/python/3.9.21/lib/python3.9/urllib/request.py", line 214, in urlopen
    return opener.open(url, data, timeout)
  File "/opt/python/3.9.21/lib/python3.9/urllib/request.py", line 517, in open
    response = self._open(req, data)
  File "/opt/python/3.9.21/lib/python3.9/urllib/request.py", line 534, in _open
    result = self._call_chain(self.handle_open, protocol, protocol +
  File "/opt/python/3.9.21/lib/python3.9/urllib/request.py", line 494, in _call_chain
    result = func(*args)
  File "/opt/python/3.9.21/lib/python3.9/urllib/request.py", line 1389, in https_open
    return self.do_open(http.client.HTTPSConnection, req,
  File "/opt/python/3.9.21/lib/python3.9/urllib/request.py", line 1349, in do_open
    raise URLError(err)
urllib.error.URLError: <urlopen error [Errno -2] Name or service not known>
INFO:app:*****************Prediction opening *************************
INFO:app:*****************Prediction opening *************************
INFO:app:*****************Prediction for URL started *************************
ERROR:whois.whois:Error trying to connect to socket: closing socket - [Errno -2] Name or service not known
ERROR:whois.whois:Error trying to connect to socket: closing socket - [Errno -2] Name or service not known
INFO:app:time_response 0.100683
INFO:app:domain_spf 0
INFO:app:asn_ip 1
INFO:app:time_domain_activation 0
INFO:app:time_domain_expiration 0
INFO:app:qty_ip_resolved 3
INFO:app:qty_nameservers None
INFO:app:qty_mx_servers None
INFO:app:ttl_hostname 1
INFO:app:tls_ssl_certificate 1
INFO:app:qty_redirects 0
INFO:app:url_google_index 1
INFO:app:domain_google_index 0
INFO:app:url_shortened 0
INFO:app:Domain: riveren.straw.page
INFO:app:URL: https://riveren.straw.page/
INFO:app:*****************Prediction for https://riveren.straw.page/ is Prediction says safe browsing URL *************************
ERROR:cassandra.datastax.cloud:<urlopen error [Errno -2] Name or service not known>
Traceback (most recent call last):
  File "/opt/python/3.9.21/lib/python3.9/urllib/request.py", line 1346, in do_open
    h.request(req.get_method(), req.selector, req.data, headers,
  File "/opt/python/3.9.21/lib/python3.9/http/client.py", line 1285, in request
    self._send_request(method, url, body, headers, encode_chunked)
  File "/opt/python/3.9.21/lib/python3.9/http/client.py", line 1331, in _send_request
    self.endheaders(body, encode_chunked=encode_chunked)
  File "/opt/python/3.9.21/lib/python3.9/http/client.py", line 1280, in endheaders
    self._send_output(message_body, encode_chunked=encode_chunked)
  File "/opt/python/3.9.21/lib/python3.9/http/client.py", line 1040, in _send_output
    self.send(msg)
  File "/opt/python/3.9.21/lib/python3.9/http/client.py", line 980, in send
    self.connect()
  File "/opt/python/3.9.21/lib/python3.9/http/client.py", line 1447, in connect
    super().connect()
  File "/opt/python/3.9.21/lib/python3.9/http/client.py", line 946, in connect
    self.sock = self._create_connection(
  File "/opt/python/3.9.21/lib/python3.9/socket.py", line 835, in create_connection
    for res in getaddrinfo(host, port, 0, SOCK_STREAM):
  File "/opt/python/3.9.21/lib/python3.9/socket.py", line 966, in getaddrinfo
    for res in _socket.getaddrinfo(host, port, family, type, proto, flags):
socket.gaierror: [Errno -2] Name or service not known

During handling of the above exception, another exception occurred:

Traceback (most recent call last):
  File "/tmp/8dc9524939e911d/antenv/lib/python3.9/site-packages/cassandra/datastax/cloud/__init__.py", line 137, in read_metadata_info
    response = urlopen(url, context=config.ssl_context, timeout=timeout)
  File "/opt/python/3.9.21/lib/python3.9/urllib/request.py", line 214, in urlopen
    return opener.open(url, data, timeout)
  File "/opt/python/3.9.21/lib/python3.9/urllib/request.py", line 517, in open
    response = self._open(req, data)
  File "/opt/python/3.9.21/lib/python3.9/urllib/request.py", line 534, in _open
    result = self._call_chain(self.handle_open, protocol, protocol +
  File "/opt/python/3.9.21/lib/python3.9/urllib/request.py", line 494, in _call_chain
    result = func(*args)
  File "/opt/python/3.9.21/lib/python3.9/urllib/request.py", line 1389, in https_open
    return self.do_open(http.client.HTTPSConnection, req,
  File "/opt/python/3.9.21/lib/python3.9/urllib/request.py", line 1349, in do_open
    raise URLError(err)
urllib.error.URLError: <urlopen error [Errno -2] Name or service not known>
ERROR:app:*****************Database is not working*************************
INFO:app:*****************Prediction for URL started *************************
INFO:app:time_response 0.586245
INFO:app:domain_spf 1
INFO:app:asn_ip 1
INFO:app:time_domain_activation 0
INFO:app:time_domain_expiration 364
INFO:app:qty_ip_resolved 1
INFO:app:qty_nameservers 2
INFO:app:qty_mx_servers 1
INFO:app:ttl_hostname 2
INFO:app:tls_ssl_certificate 1
INFO:app:qty_redirects 0
INFO:app:url_google_index 1
INFO:app:domain_google_index 0
INFO:app:url_shortened 0
INFO:app:Domain: sonuncu-sergiledigimiz-bulgulardan-hep-iyisine-geldi.com
INFO:app:URL: https://sonuncu-sergiledigimiz-bulgulardan-hep-iyisine-geldi.com/sadece-online-ozel/
INFO:app:*****************Prediction for https://sonuncu-sergiledigimiz-bulgulardan-hep-iyisine-geldi.com/sadece-online-ozel/ is Prediction says phishing URL *************************
ERROR:cassandra.datastax.cloud:<urlopen error [Errno -2] Name or service not known>
Traceback (most recent call last):
  File "/opt/python/3.9.21/lib/python3.9/urllib/request.py", line 1346, in do_open
    h.request(req.get_method(), req.selector, req.data, headers,
  File "/opt/python/3.9.21/lib/python3.9/http/client.py", line 1285, in request
    self._send_request(method, url, body, headers, encode_chunked)
  File "/opt/python/3.9.21/lib/python3.9/http/client.py", line 1331, in _send_request
    self.endheaders(body, encode_chunked=encode_chunked)
  File "/opt/python/3.9.21/lib/python3.9/http/client.py", line 1280, in endheaders
    self._send_output(message_body, encode_chunked=encode_chunked)
  File "/opt/python/3.9.21/lib/python3.9/http/client.py", line 1040, in _send_output
    self.send(msg)
  File "/opt/python/3.9.21/lib/python3.9/http/client.py", line 980, in send
    self.connect()
  File "/opt/python/3.9.21/lib/python3.9/http/client.py", line 1447, in connect
    super().connect()
  File "/opt/python/3.9.21/lib/python3.9/http/client.py", line 946, in connect
    self.sock = self._create_connection(
  File "/opt/python/3.9.21/lib/python3.9/socket.py", line 835, in create_connection
    for res in getaddrinfo(host, port, 0, SOCK_STREAM):
  File "/opt/python/3.9.21/lib/python3.9/socket.py", line 966, in getaddrinfo
    for res in _socket.getaddrinfo(host, port, family, type, proto, flags):
socket.gaierror: [Errno -2] Name or service not known

During handling of the above exception, another exception occurred:

Traceback (most recent call last):
  File "/tmp/8dc9524939e911d/antenv/lib/python3.9/site-packages/cassandra/datastax/cloud/__init__.py", line 137, in read_metadata_info
    response = urlopen(url, context=config.ssl_context, timeout=timeout)
  File "/opt/python/3.9.21/lib/python3.9/urllib/request.py", line 214, in urlopen
    return opener.open(url, data, timeout)
  File "/opt/python/3.9.21/lib/python3.9/urllib/request.py", line 517, in open
    response = self._open(req, data)
  File "/opt/python/3.9.21/lib/python3.9/urllib/request.py", line 534, in _open
    result = self._call_chain(self.handle_open, protocol, protocol +
  File "/opt/python/3.9.21/lib/python3.9/urllib/request.py", line 494, in _call_chain
    result = func(*args)
  File "/opt/python/3.9.21/lib/python3.9/urllib/request.py", line 1389, in https_open
    return self.do_open(http.client.HTTPSConnection, req,
  File "/opt/python/3.9.21/lib/python3.9/urllib/request.py", line 1349, in do_open
    raise URLError(err)
urllib.error.URLError: <urlopen error [Errno -2] Name or service not known>
ERROR:app:*****************Database is not working*************************
