DEBUG:appServiceAppLogs:Waiting for the logs flag to be set
INFO:appsvc_profiler.installer:Code Profiler Installer is starting up
INFO:appsvc_profiler.installer:Cleaning up any existing status file which indicated signal handlers initialized status
INFO:appsvc_profiler.installer:Attempting to delete the signal_handler status file for instance id b48e99ae39c2631bdbfaff480078c704864fb7435737f78ac9c0af67dc0f25d5
INFO:appsvc_profiler.installer:successfully deleted the status file
DEBUG:appsvc_profiler.installer:APPSETTING_WEBSITE_ENABLE_DEFAULT_CODE_PROFILER : None
INFO:appsvc_profiler.installer:Attempting to install the default code profiler.
DEBUG:appsvc_profiler.installer:viztracer would save traces to /tmp/b48e99_profiler_trace.json
INFO:appsvc_profiler.installer:Successfully installed code profiler.
INFO:appsvc_profiler.installer:Signal Handlers SIGUSR for needed code-profiler have been initialized for gunicorn process on instance b48e99ae39c2631bdbfaff480078c704864fb7435737f78ac9c0af67dc0f25d5
DEBUG:appsvc_profiler.installer:Code Profiler Installer is exiting as installation is completed
ERROR:app:Exception on /robots933456.txt [GET]
Traceback (most recent call last):
  File "/tmp/8dc7167740e9d97/antenv/lib/python3.9/site-packages/urllib3/connection.py", line 198, in _new_conn
    sock = connection.create_connection(
  File "/tmp/8dc7167740e9d97/antenv/lib/python3.9/site-packages/urllib3/util/connection.py", line 60, in create_connection
    for res in socket.getaddrinfo(host, port, family, socket.SOCK_STREAM):
  File "/opt/python/3.9.18/lib/python3.9/socket.py", line 954, in getaddrinfo
    for res in _socket.getaddrinfo(host, port, family, type, proto, flags):
socket.gaierror: [Errno -3] Temporary failure in name resolution

The above exception was the direct cause of the following exception:

Traceback (most recent call last):
  File "/tmp/8dc7167740e9d97/antenv/lib/python3.9/site-packages/urllib3/connectionpool.py", line 793, in urlopen
    response = self._make_request(
  File "/tmp/8dc7167740e9d97/antenv/lib/python3.9/site-packages/urllib3/connectionpool.py", line 491, in _make_request
    raise new_e
  File "/tmp/8dc7167740e9d97/antenv/lib/python3.9/site-packages/urllib3/connectionpool.py", line 467, in _make_request
    self._validate_conn(conn)
  File "/tmp/8dc7167740e9d97/antenv/lib/python3.9/site-packages/urllib3/connectionpool.py", line 1099, in _validate_conn
    conn.connect()
  File "/tmp/8dc7167740e9d97/antenv/lib/python3.9/site-packages/urllib3/connection.py", line 616, in connect
    self.sock = sock = self._new_conn()
  File "/tmp/8dc7167740e9d97/antenv/lib/python3.9/site-packages/urllib3/connection.py", line 205, in _new_conn
    raise NameResolutionError(self.host, self, e) from e
urllib3.exceptions.NameResolutionError: <urllib3.connection.HTTPSConnection object at 0x7c125e7ca190>: Failed to resolve 'api.github.com' ([Errno -3] Temporary failure in name resolution)

The above exception was the direct cause of the following exception:

Traceback (most recent call last):
  File "/tmp/8dc7167740e9d97/antenv/lib/python3.9/site-packages/requests/adapters.py", line 486, in send
    resp = conn.urlopen(
  File "/tmp/8dc7167740e9d97/antenv/lib/python3.9/site-packages/urllib3/connectionpool.py", line 847, in urlopen
    retries = retries.increment(
  File "/tmp/8dc7167740e9d97/antenv/lib/python3.9/site-packages/urllib3/util/retry.py", line 515, in increment
    raise MaxRetryError(_pool, url, reason) from reason  # type: ignore[arg-type]
urllib3.exceptions.MaxRetryError: HTTPSConnectionPool(host='api.github.com', port=443): Max retries exceeded with url: /repos/rishabh11336/Log-Phishing-Detection/git/refs/heads/main (Caused by NameResolutionError("<urllib3.connection.HTTPSConnection object at 0x7c125e7ca190>: Failed to resolve 'api.github.com' ([Errno -3] Temporary failure in name resolution)"))

During handling of the above exception, another exception occurred:

Traceback (most recent call last):
  File "/tmp/8dc7167740e9d97/antenv/lib/python3.9/site-packages/flask/app.py", line 1463, in wsgi_app
    response = self.full_dispatch_request()
  File "/tmp/8dc7167740e9d97/antenv/lib/python3.9/site-packages/flask/app.py", line 873, in full_dispatch_request
    return self.finalize_request(rv)
  File "/tmp/8dc7167740e9d97/antenv/lib/python3.9/site-packages/flask/app.py", line 894, in finalize_request
    response = self.process_response(response)
  File "/tmp/8dc7167740e9d97/antenv/lib/python3.9/site-packages/flask/app.py", line 1271, in process_response
    response = self.ensure_sync(func)(response)
  File "/tmp/8dc7167740e9d97/app.py", line 116, in after_request
    commit_to_github(commit_message=commit_message)
  File "/tmp/8dc7167740e9d97/Logging/logcommit.py", line 93, in commit_to_github
    to_github(
  File "/tmp/8dc7167740e9d97/Logging/logcommit.py", line 78, in to_github
    response = requests.patch(url, json=ref_data, headers=headers)
  File "/tmp/8dc7167740e9d97/antenv/lib/python3.9/site-packages/requests/api.py", line 145, in patch
    return request("patch", url, data=data, **kwargs)
  File "/tmp/8dc7167740e9d97/antenv/lib/python3.9/site-packages/requests/api.py", line 59, in request
    return session.request(method=method, url=url, **kwargs)
  File "/tmp/8dc7167740e9d97/antenv/lib/python3.9/site-packages/requests/sessions.py", line 589, in request
    resp = self.send(prep, **send_kwargs)
  File "/tmp/8dc7167740e9d97/antenv/lib/python3.9/site-packages/requests/sessions.py", line 703, in send
    r = adapter.send(request, **kwargs)
  File "/tmp/8dc7167740e9d97/antenv/lib/python3.9/site-packages/requests/adapters.py", line 519, in send
    raise ConnectionError(e, request=request)
requests.exceptions.ConnectionError: HTTPSConnectionPool(host='api.github.com', port=443): Max retries exceeded with url: /repos/rishabh11336/Log-Phishing-Detection/git/refs/heads/main (Caused by NameResolutionError("<urllib3.connection.HTTPSConnection object at 0x7c125e7ca190>: Failed to resolve 'api.github.com' ([Errno -3] Temporary failure in name resolution)"))
ERROR:app:Exception on /robots933456.txt [GET]
Traceback (most recent call last):
  File "/tmp/8dc7167740e9d97/antenv/lib/python3.9/site-packages/urllib3/connection.py", line 198, in _new_conn
    sock = connection.create_connection(
  File "/tmp/8dc7167740e9d97/antenv/lib/python3.9/site-packages/urllib3/util/connection.py", line 60, in create_connection
    for res in socket.getaddrinfo(host, port, family, socket.SOCK_STREAM):
  File "/opt/python/3.9.18/lib/python3.9/socket.py", line 954, in getaddrinfo
    for res in _socket.getaddrinfo(host, port, family, type, proto, flags):
socket.gaierror: [Errno -3] Temporary failure in name resolution

The above exception was the direct cause of the following exception:

Traceback (most recent call last):
  File "/tmp/8dc7167740e9d97/antenv/lib/python3.9/site-packages/urllib3/connectionpool.py", line 793, in urlopen
    response = self._make_request(
  File "/tmp/8dc7167740e9d97/antenv/lib/python3.9/site-packages/urllib3/connectionpool.py", line 491, in _make_request
    raise new_e
  File "/tmp/8dc7167740e9d97/antenv/lib/python3.9/site-packages/urllib3/connectionpool.py", line 467, in _make_request
    self._validate_conn(conn)
  File "/tmp/8dc7167740e9d97/antenv/lib/python3.9/site-packages/urllib3/connectionpool.py", line 1099, in _validate_conn
    conn.connect()
  File "/tmp/8dc7167740e9d97/antenv/lib/python3.9/site-packages/urllib3/connection.py", line 616, in connect
    self.sock = sock = self._new_conn()
  File "/tmp/8dc7167740e9d97/antenv/lib/python3.9/site-packages/urllib3/connection.py", line 205, in _new_conn
    raise NameResolutionError(self.host, self, e) from e
urllib3.exceptions.NameResolutionError: <urllib3.connection.HTTPSConnection object at 0x7c1258ca1370>: Failed to resolve 'api.github.com' ([Errno -3] Temporary failure in name resolution)

The above exception was the direct cause of the following exception:

Traceback (most recent call last):
  File "/tmp/8dc7167740e9d97/antenv/lib/python3.9/site-packages/requests/adapters.py", line 486, in send
    resp = conn.urlopen(
  File "/tmp/8dc7167740e9d97/antenv/lib/python3.9/site-packages/urllib3/connectionpool.py", line 847, in urlopen
    retries = retries.increment(
  File "/tmp/8dc7167740e9d97/antenv/lib/python3.9/site-packages/urllib3/util/retry.py", line 515, in increment
    raise MaxRetryError(_pool, url, reason) from reason  # type: ignore[arg-type]
urllib3.exceptions.MaxRetryError: HTTPSConnectionPool(host='api.github.com', port=443): Max retries exceeded with url: /repos/rishabh11336/Log-Phishing-Detection/git/refs/heads/main (Caused by NameResolutionError("<urllib3.connection.HTTPSConnection object at 0x7c1258ca1370>: Failed to resolve 'api.github.com' ([Errno -3] Temporary failure in name resolution)"))

During handling of the above exception, another exception occurred:

Traceback (most recent call last):
  File "/tmp/8dc7167740e9d97/antenv/lib/python3.9/site-packages/flask/app.py", line 1463, in wsgi_app
    response = self.full_dispatch_request()
  File "/tmp/8dc7167740e9d97/antenv/lib/python3.9/site-packages/flask/app.py", line 873, in full_dispatch_request
    return self.finalize_request(rv)
  File "/tmp/8dc7167740e9d97/antenv/lib/python3.9/site-packages/flask/app.py", line 894, in finalize_request
    response = self.process_response(response)
  File "/tmp/8dc7167740e9d97/antenv/lib/python3.9/site-packages/flask/app.py", line 1271, in process_response
    response = self.ensure_sync(func)(response)
  File "/tmp/8dc7167740e9d97/app.py", line 116, in after_request
    commit_to_github(commit_message=commit_message)
  File "/tmp/8dc7167740e9d97/Logging/logcommit.py", line 93, in commit_to_github
    to_github(
  File "/tmp/8dc7167740e9d97/Logging/logcommit.py", line 78, in to_github
    response = requests.patch(url, json=ref_data, headers=headers)
  File "/tmp/8dc7167740e9d97/antenv/lib/python3.9/site-packages/requests/api.py", line 145, in patch
    return request("patch", url, data=data, **kwargs)
  File "/tmp/8dc7167740e9d97/antenv/lib/python3.9/site-packages/requests/api.py", line 59, in request
    return session.request(method=method, url=url, **kwargs)
  File "/tmp/8dc7167740e9d97/antenv/lib/python3.9/site-packages/requests/sessions.py", line 589, in request
    resp = self.send(prep, **send_kwargs)
  File "/tmp/8dc7167740e9d97/antenv/lib/python3.9/site-packages/requests/sessions.py", line 703, in send
    r = adapter.send(request, **kwargs)
  File "/tmp/8dc7167740e9d97/antenv/lib/python3.9/site-packages/requests/adapters.py", line 519, in send
    raise ConnectionError(e, request=request)
requests.exceptions.ConnectionError: HTTPSConnectionPool(host='api.github.com', port=443): Max retries exceeded with url: /repos/rishabh11336/Log-Phishing-Detection/git/refs/heads/main (Caused by NameResolutionError("<urllib3.connection.HTTPSConnection object at 0x7c1258ca1370>: Failed to resolve 'api.github.com' ([Errno -3] Temporary failure in name resolution)"))
