INFO:appsvc_profiler.installer:Code Profiler Installer is starting up
INFO:appsvc_profiler.installer:Cleaning up any existing status file which indicated signal handlers initialized status
INFO:appsvc_profiler.installer:Attempting to delete the signal_handler status file for instance id 1e94db65c56587b74b0d8f52a80aa0a2a9a213bd6f66e280ee4d42652e7c2bc0
INFO:appsvc_profiler.installer:successfully deleted the status file
DEBUG:appsvc_profiler.installer:APPSETTING_WEBSITE_ENABLE_DEFAULT_CODE_PROFILER : None
INFO:appsvc_profiler.installer:Attempting to install the default code profiler.
DEBUG:appsvc_profiler.installer:viztracer would save traces to /tmp/1e94db_profiler_trace.json
INFO:appsvc_profiler.installer:Successfully installed code profiler.
INFO:appsvc_profiler.installer:Signal Handlers SIGUSR for needed code-profiler have been initialized for gunicorn process on instance 1e94db65c56587b74b0d8f52a80aa0a2a9a213bd6f66e280ee4d42652e7c2bc0
DEBUG:appsvc_profiler.installer:Code Profiler Installer is exiting as installation is completed
INFO:app:*****************Prediction opening *************************
INFO:app:*****************Prediction opening *************************
INFO:app:*****************Prediction opening *************************
ERROR:cassandra.datastax.cloud:HTTP Error 401: Unauthorized
Traceback (most recent call last):
  File "/tmp/8dc9524939e911d/antenv/lib/python3.9/site-packages/cassandra/datastax/cloud/__init__.py", line 137, in read_metadata_info
    response = urlopen(url, context=config.ssl_context, timeout=timeout)
  File "/opt/python/3.9.19/lib/python3.9/urllib/request.py", line 214, in urlopen
    return opener.open(url, data, timeout)
  File "/opt/python/3.9.19/lib/python3.9/urllib/request.py", line 523, in open
    response = meth(req, response)
  File "/opt/python/3.9.19/lib/python3.9/urllib/request.py", line 632, in http_response
    response = self.parent.error(
  File "/opt/python/3.9.19/lib/python3.9/urllib/request.py", line 561, in error
    return self._call_chain(*args)
  File "/opt/python/3.9.19/lib/python3.9/urllib/request.py", line 494, in _call_chain
    result = func(*args)
  File "/opt/python/3.9.19/lib/python3.9/urllib/request.py", line 641, in http_error_default
    raise HTTPError(req.full_url, code, msg, hdrs, fp)
urllib.error.HTTPError: HTTP Error 401: Unauthorized
INFO:app:*****************Prediction opening *************************
ERROR:app:Exception on / [HEAD]
Traceback (most recent call last):
  File "/tmp/8dc9524939e911d/antenv/lib/python3.9/site-packages/flask/app.py", line 1463, in wsgi_app
    response = self.full_dispatch_request()
  File "/tmp/8dc9524939e911d/antenv/lib/python3.9/site-packages/flask/app.py", line 873, in full_dispatch_request
    return self.finalize_request(rv)
  File "/tmp/8dc9524939e911d/antenv/lib/python3.9/site-packages/flask/app.py", line 892, in finalize_request
    response = self.make_response(rv)
  File "/tmp/8dc9524939e911d/antenv/lib/python3.9/site-packages/flask/app.py", line 1164, in make_response
    raise TypeError(
TypeError: The view function for 'predictui' did not return a valid response. The function either returned None or ended without a return statement.
INFO:app:*****************Prediction opening *************************
INFO:app:*****************Prediction for URL started *************************
INFO:app:*****************Prediction for URL started *************************
INFO:app:time_response 1.539365
INFO:app:domain_spf 0
INFO:app:asn_ip 1
INFO:app:time_domain_activation 4557
INFO:app:time_domain_expiration 191
INFO:app:qty_ip_resolved 4
INFO:app:qty_nameservers None
INFO:app:qty_mx_servers None
INFO:app:ttl_hostname 1
INFO:app:tls_ssl_certificate 1
INFO:app:qty_redirects 1
INFO:app:url_google_index 1
INFO:app:domain_google_index 0
INFO:app:url_shortened 0
INFO:app:Domain: www.coursera.org
INFO:app:URL: https://www.coursera.org/my-learning?myLearningTab=IN_PROGRESS
INFO:app:*****************Prediction for https://www.coursera.org/my-learning?myLearningTab=IN_PROGRESS is Prediction says phishing URL *************************
ERROR:cassandra.datastax.cloud:HTTP Error 401: Unauthorized
Traceback (most recent call last):
  File "/tmp/8dc9524939e911d/antenv/lib/python3.9/site-packages/cassandra/datastax/cloud/__init__.py", line 137, in read_metadata_info
    response = urlopen(url, context=config.ssl_context, timeout=timeout)
  File "/opt/python/3.9.19/lib/python3.9/urllib/request.py", line 214, in urlopen
    return opener.open(url, data, timeout)
  File "/opt/python/3.9.19/lib/python3.9/urllib/request.py", line 523, in open
    response = meth(req, response)
  File "/opt/python/3.9.19/lib/python3.9/urllib/request.py", line 632, in http_response
    response = self.parent.error(
  File "/opt/python/3.9.19/lib/python3.9/urllib/request.py", line 561, in error
    return self._call_chain(*args)
  File "/opt/python/3.9.19/lib/python3.9/urllib/request.py", line 494, in _call_chain
    result = func(*args)
  File "/opt/python/3.9.19/lib/python3.9/urllib/request.py", line 641, in http_error_default
    raise HTTPError(req.full_url, code, msg, hdrs, fp)
urllib.error.HTTPError: HTTP Error 401: Unauthorized
ERROR:app:*****************Database is not working*************************
INFO:app:*****************Prediction for URL started *************************
INFO:app:time_response 0.033654
INFO:app:domain_spf 0
INFO:app:asn_ip 1
INFO:app:time_domain_activation 9789
INFO:app:time_domain_expiration 1532
INFO:app:qty_ip_resolved 4
INFO:app:qty_nameservers None
INFO:app:qty_mx_servers None
INFO:app:ttl_hostname 1
INFO:app:tls_ssl_certificate 1
INFO:app:qty_redirects 3
INFO:app:url_google_index 1
INFO:app:domain_google_index 0
INFO:app:url_shortened 0
INFO:app:Domain: mail.google.com
INFO:app:URL: https://mail.google.com/mail/u/0/#inbox
INFO:app:*****************Prediction for https://mail.google.com/mail/u/0/#inbox is Prediction says safe browsing URL *************************
ERROR:cassandra.datastax.cloud:HTTP Error 401: Unauthorized
Traceback (most recent call last):
  File "/tmp/8dc9524939e911d/antenv/lib/python3.9/site-packages/cassandra/datastax/cloud/__init__.py", line 137, in read_metadata_info
    response = urlopen(url, context=config.ssl_context, timeout=timeout)
  File "/opt/python/3.9.19/lib/python3.9/urllib/request.py", line 214, in urlopen
    return opener.open(url, data, timeout)
  File "/opt/python/3.9.19/lib/python3.9/urllib/request.py", line 523, in open
    response = meth(req, response)
  File "/opt/python/3.9.19/lib/python3.9/urllib/request.py", line 632, in http_response
    response = self.parent.error(
  File "/opt/python/3.9.19/lib/python3.9/urllib/request.py", line 561, in error
    return self._call_chain(*args)
  File "/opt/python/3.9.19/lib/python3.9/urllib/request.py", line 494, in _call_chain
    result = func(*args)
  File "/opt/python/3.9.19/lib/python3.9/urllib/request.py", line 641, in http_error_default
    raise HTTPError(req.full_url, code, msg, hdrs, fp)
urllib.error.HTTPError: HTTP Error 401: Unauthorized
ERROR:app:*****************Database is not working*************************
ERROR:cassandra.datastax.cloud:HTTP Error 401: Unauthorized
Traceback (most recent call last):
  File "/tmp/8dc9524939e911d/antenv/lib/python3.9/site-packages/cassandra/datastax/cloud/__init__.py", line 137, in read_metadata_info
    response = urlopen(url, context=config.ssl_context, timeout=timeout)
  File "/opt/python/3.9.19/lib/python3.9/urllib/request.py", line 214, in urlopen
    return opener.open(url, data, timeout)
  File "/opt/python/3.9.19/lib/python3.9/urllib/request.py", line 523, in open
    response = meth(req, response)
  File "/opt/python/3.9.19/lib/python3.9/urllib/request.py", line 632, in http_response
    response = self.parent.error(
  File "/opt/python/3.9.19/lib/python3.9/urllib/request.py", line 561, in error
    return self._call_chain(*args)
  File "/opt/python/3.9.19/lib/python3.9/urllib/request.py", line 494, in _call_chain
    result = func(*args)
  File "/opt/python/3.9.19/lib/python3.9/urllib/request.py", line 641, in http_error_default
    raise HTTPError(req.full_url, code, msg, hdrs, fp)
urllib.error.HTTPError: HTTP Error 401: Unauthorized
ERROR:cassandra.datastax.cloud:HTTP Error 401: Unauthorized
Traceback (most recent call last):
  File "/tmp/8dc9524939e911d/antenv/lib/python3.9/site-packages/cassandra/datastax/cloud/__init__.py", line 137, in read_metadata_info
    response = urlopen(url, context=config.ssl_context, timeout=timeout)
  File "/opt/python/3.9.19/lib/python3.9/urllib/request.py", line 214, in urlopen
    return opener.open(url, data, timeout)
  File "/opt/python/3.9.19/lib/python3.9/urllib/request.py", line 523, in open
    response = meth(req, response)
  File "/opt/python/3.9.19/lib/python3.9/urllib/request.py", line 632, in http_response
    response = self.parent.error(
  File "/opt/python/3.9.19/lib/python3.9/urllib/request.py", line 561, in error
    return self._call_chain(*args)
  File "/opt/python/3.9.19/lib/python3.9/urllib/request.py", line 494, in _call_chain
    result = func(*args)
  File "/opt/python/3.9.19/lib/python3.9/urllib/request.py", line 641, in http_error_default
    raise HTTPError(req.full_url, code, msg, hdrs, fp)
urllib.error.HTTPError: HTTP Error 401: Unauthorized
INFO:app:*****************Prediction opening *************************
ERROR:cassandra.datastax.cloud:HTTP Error 401: Unauthorized
Traceback (most recent call last):
  File "/tmp/8dc9524939e911d/antenv/lib/python3.9/site-packages/cassandra/datastax/cloud/__init__.py", line 137, in read_metadata_info
    response = urlopen(url, context=config.ssl_context, timeout=timeout)
  File "/opt/python/3.9.19/lib/python3.9/urllib/request.py", line 214, in urlopen
    return opener.open(url, data, timeout)
  File "/opt/python/3.9.19/lib/python3.9/urllib/request.py", line 523, in open
    response = meth(req, response)
  File "/opt/python/3.9.19/lib/python3.9/urllib/request.py", line 632, in http_response
    response = self.parent.error(
  File "/opt/python/3.9.19/lib/python3.9/urllib/request.py", line 561, in error
    return self._call_chain(*args)
  File "/opt/python/3.9.19/lib/python3.9/urllib/request.py", line 494, in _call_chain
    result = func(*args)
  File "/opt/python/3.9.19/lib/python3.9/urllib/request.py", line 641, in http_error_default
    raise HTTPError(req.full_url, code, msg, hdrs, fp)
urllib.error.HTTPError: HTTP Error 401: Unauthorized
INFO:app:*****************Prediction opening *************************
INFO:app:*****************Prediction opening *************************
INFO:app:*****************Prediction opening *************************
ERROR:cassandra.datastax.cloud:HTTP Error 401: Unauthorized
Traceback (most recent call last):
  File "/tmp/8dc9524939e911d/antenv/lib/python3.9/site-packages/cassandra/datastax/cloud/__init__.py", line 137, in read_metadata_info
    response = urlopen(url, context=config.ssl_context, timeout=timeout)
  File "/opt/python/3.9.19/lib/python3.9/urllib/request.py", line 214, in urlopen
    return opener.open(url, data, timeout)
  File "/opt/python/3.9.19/lib/python3.9/urllib/request.py", line 523, in open
    response = meth(req, response)
  File "/opt/python/3.9.19/lib/python3.9/urllib/request.py", line 632, in http_response
    response = self.parent.error(
  File "/opt/python/3.9.19/lib/python3.9/urllib/request.py", line 561, in error
    return self._call_chain(*args)
  File "/opt/python/3.9.19/lib/python3.9/urllib/request.py", line 494, in _call_chain
    result = func(*args)
  File "/opt/python/3.9.19/lib/python3.9/urllib/request.py", line 641, in http_error_default
    raise HTTPError(req.full_url, code, msg, hdrs, fp)
urllib.error.HTTPError: HTTP Error 401: Unauthorized
INFO:app:*****************Prediction opening *************************
ERROR:cassandra.datastax.cloud:HTTP Error 401: Unauthorized
Traceback (most recent call last):
  File "/tmp/8dc9524939e911d/antenv/lib/python3.9/site-packages/cassandra/datastax/cloud/__init__.py", line 137, in read_metadata_info
    response = urlopen(url, context=config.ssl_context, timeout=timeout)
  File "/opt/python/3.9.19/lib/python3.9/urllib/request.py", line 214, in urlopen
    return opener.open(url, data, timeout)
  File "/opt/python/3.9.19/lib/python3.9/urllib/request.py", line 523, in open
    response = meth(req, response)
  File "/opt/python/3.9.19/lib/python3.9/urllib/request.py", line 632, in http_response
    response = self.parent.error(
  File "/opt/python/3.9.19/lib/python3.9/urllib/request.py", line 561, in error
    return self._call_chain(*args)
  File "/opt/python/3.9.19/lib/python3.9/urllib/request.py", line 494, in _call_chain
    result = func(*args)
  File "/opt/python/3.9.19/lib/python3.9/urllib/request.py", line 641, in http_error_default
    raise HTTPError(req.full_url, code, msg, hdrs, fp)
urllib.error.HTTPError: HTTP Error 401: Unauthorized
INFO:app:*****************Prediction opening *************************
ERROR:cassandra.datastax.cloud:HTTP Error 401: Unauthorized
Traceback (most recent call last):
  File "/tmp/8dc9524939e911d/antenv/lib/python3.9/site-packages/cassandra/datastax/cloud/__init__.py", line 137, in read_metadata_info
    response = urlopen(url, context=config.ssl_context, timeout=timeout)
  File "/opt/python/3.9.19/lib/python3.9/urllib/request.py", line 214, in urlopen
    return opener.open(url, data, timeout)
  File "/opt/python/3.9.19/lib/python3.9/urllib/request.py", line 523, in open
    response = meth(req, response)
  File "/opt/python/3.9.19/lib/python3.9/urllib/request.py", line 632, in http_response
    response = self.parent.error(
  File "/opt/python/3.9.19/lib/python3.9/urllib/request.py", line 561, in error
    return self._call_chain(*args)
  File "/opt/python/3.9.19/lib/python3.9/urllib/request.py", line 494, in _call_chain
    result = func(*args)
  File "/opt/python/3.9.19/lib/python3.9/urllib/request.py", line 641, in http_error_default
    raise HTTPError(req.full_url, code, msg, hdrs, fp)
urllib.error.HTTPError: HTTP Error 401: Unauthorized
INFO:app:*****************Prediction opening *************************
INFO:app:*****************Prediction opening *************************
INFO:app:*****************Prediction for URL started *************************
INFO:app:time_response 0.256703
INFO:app:domain_spf 0
INFO:app:asn_ip 1
INFO:app:time_domain_activation 5428
INFO:app:time_domain_expiration 50
INFO:app:qty_ip_resolved 1
INFO:app:qty_nameservers None
INFO:app:qty_mx_servers None
INFO:app:ttl_hostname 3
INFO:app:tls_ssl_certificate 1
INFO:app:qty_redirects 0
INFO:app:url_google_index 1
INFO:app:domain_google_index 0
INFO:app:url_shortened 0
INFO:app:Domain: www.kaggle.com
INFO:app:URL: https://www.kaggle.com/learn/intro-to-deep-learning/course
INFO:app:*****************Prediction for https://www.kaggle.com/learn/intro-to-deep-learning/course is Prediction says phishing URL *************************
ERROR:cassandra.datastax.cloud:HTTP Error 401: Unauthorized
Traceback (most recent call last):
  File "/tmp/8dc9524939e911d/antenv/lib/python3.9/site-packages/cassandra/datastax/cloud/__init__.py", line 137, in read_metadata_info
    response = urlopen(url, context=config.ssl_context, timeout=timeout)
  File "/opt/python/3.9.19/lib/python3.9/urllib/request.py", line 214, in urlopen
    return opener.open(url, data, timeout)
  File "/opt/python/3.9.19/lib/python3.9/urllib/request.py", line 523, in open
    response = meth(req, response)
  File "/opt/python/3.9.19/lib/python3.9/urllib/request.py", line 632, in http_response
    response = self.parent.error(
  File "/opt/python/3.9.19/lib/python3.9/urllib/request.py", line 561, in error
    return self._call_chain(*args)
  File "/opt/python/3.9.19/lib/python3.9/urllib/request.py", line 494, in _call_chain
    result = func(*args)
  File "/opt/python/3.9.19/lib/python3.9/urllib/request.py", line 641, in http_error_default
    raise HTTPError(req.full_url, code, msg, hdrs, fp)
urllib.error.HTTPError: HTTP Error 401: Unauthorized
ERROR:app:*****************Database is not working*************************
INFO:app:*****************Prediction for URL started *************************
INFO:app:time_response 0.251791
INFO:app:domain_spf 1
INFO:app:asn_ip 1
INFO:app:time_domain_activation 6117
INFO:app:time_domain_expiration 92
INFO:app:qty_ip_resolved 1
INFO:app:qty_nameservers 8
INFO:app:qty_mx_servers 5
INFO:app:ttl_hostname 1
INFO:app:tls_ssl_certificate 1
INFO:app:qty_redirects 0
INFO:app:url_google_index 1
INFO:app:domain_google_index 0
INFO:app:url_shortened 0
INFO:app:Domain: github.com
INFO:app:URL: https://github.com/rishabh11336
INFO:app:*****************Prediction for https://github.com/rishabh11336 is Prediction says safe browsing URL *************************
ERROR:cassandra.datastax.cloud:HTTP Error 401: Unauthorized
Traceback (most recent call last):
  File "/tmp/8dc9524939e911d/antenv/lib/python3.9/site-packages/cassandra/datastax/cloud/__init__.py", line 137, in read_metadata_info
    response = urlopen(url, context=config.ssl_context, timeout=timeout)
  File "/opt/python/3.9.19/lib/python3.9/urllib/request.py", line 214, in urlopen
    return opener.open(url, data, timeout)
  File "/opt/python/3.9.19/lib/python3.9/urllib/request.py", line 523, in open
    response = meth(req, response)
  File "/opt/python/3.9.19/lib/python3.9/urllib/request.py", line 632, in http_response
    response = self.parent.error(
  File "/opt/python/3.9.19/lib/python3.9/urllib/request.py", line 561, in error
    return self._call_chain(*args)
  File "/opt/python/3.9.19/lib/python3.9/urllib/request.py", line 494, in _call_chain
    result = func(*args)
  File "/opt/python/3.9.19/lib/python3.9/urllib/request.py", line 641, in http_error_default
    raise HTTPError(req.full_url, code, msg, hdrs, fp)
urllib.error.HTTPError: HTTP Error 401: Unauthorized
ERROR:app:*****************Database is not working*************************
INFO:app:*****************Prediction for URL started *************************
DEBUG:appServiceAppLogs:Waiting for the logs flag to be set
INFO:appsvc_profiler.installer:Code Profiler Installer is starting up
INFO:appsvc_profiler.installer:Cleaning up any existing status file which indicated signal handlers initialized status
INFO:appsvc_profiler.installer:Attempting to delete the signal_handler status file for instance id 1e94db65c56587b74b0d8f52a80aa0a2a9a213bd6f66e280ee4d42652e7c2bc0
INFO:appsvc_profiler.installer:successfully deleted the status file
DEBUG:appsvc_profiler.installer:APPSETTING_WEBSITE_ENABLE_DEFAULT_CODE_PROFILER : None
INFO:appsvc_profiler.installer:Attempting to install the default code profiler.
DEBUG:appsvc_profiler.installer:viztracer would save traces to /tmp/1e94db_profiler_trace.json
INFO:appsvc_profiler.installer:Successfully installed code profiler.
INFO:appsvc_profiler.installer:Signal Handlers SIGUSR for needed code-profiler have been initialized for gunicorn process on instance 1e94db65c56587b74b0d8f52a80aa0a2a9a213bd6f66e280ee4d42652e7c2bc0
DEBUG:appsvc_profiler.installer:Code Profiler Installer is exiting as installation is completed
INFO:app:*****************Prediction opening *************************
ERROR:cassandra.datastax.cloud:HTTP Error 401: Unauthorized
Traceback (most recent call last):
  File "/tmp/8dc9524939e911d/antenv/lib/python3.9/site-packages/cassandra/datastax/cloud/__init__.py", line 137, in read_metadata_info
    response = urlopen(url, context=config.ssl_context, timeout=timeout)
  File "/opt/python/3.9.19/lib/python3.9/urllib/request.py", line 214, in urlopen
    return opener.open(url, data, timeout)
  File "/opt/python/3.9.19/lib/python3.9/urllib/request.py", line 523, in open
    response = meth(req, response)
  File "/opt/python/3.9.19/lib/python3.9/urllib/request.py", line 632, in http_response
    response = self.parent.error(
  File "/opt/python/3.9.19/lib/python3.9/urllib/request.py", line 561, in error
    return self._call_chain(*args)
  File "/opt/python/3.9.19/lib/python3.9/urllib/request.py", line 494, in _call_chain
    result = func(*args)
  File "/opt/python/3.9.19/lib/python3.9/urllib/request.py", line 641, in http_error_default
    raise HTTPError(req.full_url, code, msg, hdrs, fp)
urllib.error.HTTPError: HTTP Error 401: Unauthorized
ERROR:cassandra.datastax.cloud:HTTP Error 401: Unauthorized
Traceback (most recent call last):
  File "/tmp/8dc9524939e911d/antenv/lib/python3.9/site-packages/cassandra/datastax/cloud/__init__.py", line 137, in read_metadata_info
    response = urlopen(url, context=config.ssl_context, timeout=timeout)
  File "/opt/python/3.9.19/lib/python3.9/urllib/request.py", line 214, in urlopen
    return opener.open(url, data, timeout)
  File "/opt/python/3.9.19/lib/python3.9/urllib/request.py", line 523, in open
    response = meth(req, response)
  File "/opt/python/3.9.19/lib/python3.9/urllib/request.py", line 632, in http_response
    response = self.parent.error(
  File "/opt/python/3.9.19/lib/python3.9/urllib/request.py", line 561, in error
    return self._call_chain(*args)
  File "/opt/python/3.9.19/lib/python3.9/urllib/request.py", line 494, in _call_chain
    result = func(*args)
  File "/opt/python/3.9.19/lib/python3.9/urllib/request.py", line 641, in http_error_default
    raise HTTPError(req.full_url, code, msg, hdrs, fp)
urllib.error.HTTPError: HTTP Error 401: Unauthorized
INFO:app:*****************Prediction opening *************************
INFO:app:*****************Prediction opening *************************
INFO:app:*****************Prediction opening *************************
ERROR:app:Exception on / [HEAD]
Traceback (most recent call last):
  File "/tmp/8dc9524939e911d/antenv/lib/python3.9/site-packages/flask/app.py", line 1463, in wsgi_app
    response = self.full_dispatch_request()
  File "/tmp/8dc9524939e911d/antenv/lib/python3.9/site-packages/flask/app.py", line 873, in full_dispatch_request
    return self.finalize_request(rv)
  File "/tmp/8dc9524939e911d/antenv/lib/python3.9/site-packages/flask/app.py", line 892, in finalize_request
    response = self.make_response(rv)
  File "/tmp/8dc9524939e911d/antenv/lib/python3.9/site-packages/flask/app.py", line 1164, in make_response
    raise TypeError(
TypeError: The view function for 'predictui' did not return a valid response. The function either returned None or ended without a return statement.
INFO:app:*****************Prediction opening *************************
INFO:app:*****************Prediction opening *************************
INFO:app:*****************Prediction opening *************************
ERROR:cassandra.datastax.cloud:HTTP Error 401: Unauthorized
Traceback (most recent call last):
  File "/tmp/8dc9524939e911d/antenv/lib/python3.9/site-packages/cassandra/datastax/cloud/__init__.py", line 137, in read_metadata_info
    response = urlopen(url, context=config.ssl_context, timeout=timeout)
  File "/opt/python/3.9.19/lib/python3.9/urllib/request.py", line 214, in urlopen
    return opener.open(url, data, timeout)
  File "/opt/python/3.9.19/lib/python3.9/urllib/request.py", line 523, in open
    response = meth(req, response)
  File "/opt/python/3.9.19/lib/python3.9/urllib/request.py", line 632, in http_response
    response = self.parent.error(
  File "/opt/python/3.9.19/lib/python3.9/urllib/request.py", line 561, in error
    return self._call_chain(*args)
  File "/opt/python/3.9.19/lib/python3.9/urllib/request.py", line 494, in _call_chain
    result = func(*args)
  File "/opt/python/3.9.19/lib/python3.9/urllib/request.py", line 641, in http_error_default
    raise HTTPError(req.full_url, code, msg, hdrs, fp)
urllib.error.HTTPError: HTTP Error 401: Unauthorized
INFO:app:*****************Prediction opening *************************
INFO:app:*****************Prediction opening *************************
INFO:app:*****************Prediction opening *************************
INFO:app:*****************Prediction for URL started *************************
INFO:app:time_response 0.090811
INFO:app:domain_spf 0
INFO:app:asn_ip 1
INFO:app:time_domain_activation 9797
INFO:app:time_domain_expiration 1524
INFO:app:qty_ip_resolved 6
INFO:app:qty_nameservers None
INFO:app:qty_mx_servers None
INFO:app:ttl_hostname 1
INFO:app:tls_ssl_certificate 1
INFO:app:qty_redirects 0
INFO:app:url_google_index 1
INFO:app:domain_google_index 0
INFO:app:url_shortened 0
INFO:app:Domain: www.google.com
INFO:app:URL: https://www.google.com/
INFO:app:*****************Prediction for https://www.google.com/ is Prediction says safe browsing URL *************************
ERROR:cassandra.datastax.cloud:HTTP Error 401: Unauthorized
Traceback (most recent call last):
  File "/tmp/8dc9524939e911d/antenv/lib/python3.9/site-packages/cassandra/datastax/cloud/__init__.py", line 137, in read_metadata_info
    response = urlopen(url, context=config.ssl_context, timeout=timeout)
  File "/opt/python/3.9.19/lib/python3.9/urllib/request.py", line 214, in urlopen
    return opener.open(url, data, timeout)
  File "/opt/python/3.9.19/lib/python3.9/urllib/request.py", line 523, in open
    response = meth(req, response)
  File "/opt/python/3.9.19/lib/python3.9/urllib/request.py", line 632, in http_response
    response = self.parent.error(
  File "/opt/python/3.9.19/lib/python3.9/urllib/request.py", line 561, in error
    return self._call_chain(*args)
  File "/opt/python/3.9.19/lib/python3.9/urllib/request.py", line 494, in _call_chain
    result = func(*args)
  File "/opt/python/3.9.19/lib/python3.9/urllib/request.py", line 641, in http_error_default
    raise HTTPError(req.full_url, code, msg, hdrs, fp)
urllib.error.HTTPError: HTTP Error 401: Unauthorized
ERROR:app:*****************Database is not working*************************
INFO:app:*****************Prediction for URL started *************************
INFO:app:time_response 0.755095
INFO:app:domain_spf 0
INFO:app:asn_ip 1
INFO:app:time_domain_activation 58
INFO:app:time_domain_expiration 306
INFO:app:qty_ip_resolved 1
INFO:app:qty_nameservers 2
INFO:app:qty_mx_servers None
INFO:app:ttl_hostname 9
INFO:app:tls_ssl_certificate 1
INFO:app:qty_redirects 1
INFO:app:url_google_index 1
INFO:app:domain_google_index 0
INFO:app:url_shortened 0
INFO:app:Domain: www.infcircle.com
INFO:app:URL: https://www.infcircle.com/
INFO:app:*****************Prediction for https://www.infcircle.com/ is Prediction says safe browsing URL *************************
ERROR:cassandra.datastax.cloud:HTTP Error 401: Unauthorized
Traceback (most recent call last):
  File "/tmp/8dc9524939e911d/antenv/lib/python3.9/site-packages/cassandra/datastax/cloud/__init__.py", line 137, in read_metadata_info
    response = urlopen(url, context=config.ssl_context, timeout=timeout)
  File "/opt/python/3.9.19/lib/python3.9/urllib/request.py", line 214, in urlopen
    return opener.open(url, data, timeout)
  File "/opt/python/3.9.19/lib/python3.9/urllib/request.py", line 523, in open
    response = meth(req, response)
  File "/opt/python/3.9.19/lib/python3.9/urllib/request.py", line 632, in http_response
    response = self.parent.error(
  File "/opt/python/3.9.19/lib/python3.9/urllib/request.py", line 561, in error
    return self._call_chain(*args)
  File "/opt/python/3.9.19/lib/python3.9/urllib/request.py", line 494, in _call_chain
    result = func(*args)
  File "/opt/python/3.9.19/lib/python3.9/urllib/request.py", line 641, in http_error_default
    raise HTTPError(req.full_url, code, msg, hdrs, fp)
urllib.error.HTTPError: HTTP Error 401: Unauthorized
ERROR:app:*****************Database is not working*************************
INFO:app:*****************Prediction opening *************************
ERROR:cassandra.datastax.cloud:HTTP Error 401: Unauthorized
Traceback (most recent call last):
  File "/tmp/8dc9524939e911d/antenv/lib/python3.9/site-packages/cassandra/datastax/cloud/__init__.py", line 137, in read_metadata_info
    response = urlopen(url, context=config.ssl_context, timeout=timeout)
  File "/opt/python/3.9.19/lib/python3.9/urllib/request.py", line 214, in urlopen
    return opener.open(url, data, timeout)
  File "/opt/python/3.9.19/lib/python3.9/urllib/request.py", line 523, in open
    response = meth(req, response)
  File "/opt/python/3.9.19/lib/python3.9/urllib/request.py", line 632, in http_response
    response = self.parent.error(
  File "/opt/python/3.9.19/lib/python3.9/urllib/request.py", line 561, in error
    return self._call_chain(*args)
  File "/opt/python/3.9.19/lib/python3.9/urllib/request.py", line 494, in _call_chain
    result = func(*args)
  File "/opt/python/3.9.19/lib/python3.9/urllib/request.py", line 641, in http_error_default
    raise HTTPError(req.full_url, code, msg, hdrs, fp)
urllib.error.HTTPError: HTTP Error 401: Unauthorized
INFO:app:*****************Prediction opening *************************
ERROR:cassandra.datastax.cloud:HTTP Error 401: Unauthorized
Traceback (most recent call last):
  File "/tmp/8dc9524939e911d/antenv/lib/python3.9/site-packages/cassandra/datastax/cloud/__init__.py", line 137, in read_metadata_info
    response = urlopen(url, context=config.ssl_context, timeout=timeout)
  File "/opt/python/3.9.19/lib/python3.9/urllib/request.py", line 214, in urlopen
    return opener.open(url, data, timeout)
  File "/opt/python/3.9.19/lib/python3.9/urllib/request.py", line 523, in open
    response = meth(req, response)
  File "/opt/python/3.9.19/lib/python3.9/urllib/request.py", line 632, in http_response
    response = self.parent.error(
  File "/opt/python/3.9.19/lib/python3.9/urllib/request.py", line 561, in error
    return self._call_chain(*args)
  File "/opt/python/3.9.19/lib/python3.9/urllib/request.py", line 494, in _call_chain
    result = func(*args)
  File "/opt/python/3.9.19/lib/python3.9/urllib/request.py", line 641, in http_error_default
    raise HTTPError(req.full_url, code, msg, hdrs, fp)
urllib.error.HTTPError: HTTP Error 401: Unauthorized
INFO:app:*****************Prediction opening *************************
ERROR:cassandra.datastax.cloud:HTTP Error 401: Unauthorized
Traceback (most recent call last):
  File "/tmp/8dc9524939e911d/antenv/lib/python3.9/site-packages/cassandra/datastax/cloud/__init__.py", line 137, in read_metadata_info
    response = urlopen(url, context=config.ssl_context, timeout=timeout)
  File "/opt/python/3.9.19/lib/python3.9/urllib/request.py", line 214, in urlopen
    return opener.open(url, data, timeout)
  File "/opt/python/3.9.19/lib/python3.9/urllib/request.py", line 523, in open
    response = meth(req, response)
  File "/opt/python/3.9.19/lib/python3.9/urllib/request.py", line 632, in http_response
    response = self.parent.error(
  File "/opt/python/3.9.19/lib/python3.9/urllib/request.py", line 561, in error
    return self._call_chain(*args)
  File "/opt/python/3.9.19/lib/python3.9/urllib/request.py", line 494, in _call_chain
    result = func(*args)
  File "/opt/python/3.9.19/lib/python3.9/urllib/request.py", line 641, in http_error_default
    raise HTTPError(req.full_url, code, msg, hdrs, fp)
urllib.error.HTTPError: HTTP Error 401: Unauthorized
INFO:app:*****************Prediction for URL started *************************
INFO:app:time_response 0.116857
INFO:app:domain_spf 0
INFO:app:asn_ip 1
INFO:app:time_domain_activation 27
INFO:app:time_domain_expiration 337
INFO:app:qty_ip_resolved 2
INFO:app:qty_nameservers 2
INFO:app:qty_mx_servers None
INFO:app:ttl_hostname 1
INFO:app:tls_ssl_certificate 1
INFO:app:qty_redirects 0
INFO:app:url_google_index 1
INFO:app:domain_google_index 0
INFO:app:url_shortened 0
INFO:app:Domain: biidingrfponlinedoucuments.click
INFO:app:URL: https://biidingrfponlinedoucuments.click/rfp/rfq/requestforquoation/redundancy/adobe/function/utilize/sequence/interprete
INFO:app:*****************Prediction for https://biidingrfponlinedoucuments.click/rfp/rfq/requestforquoation/redundancy/adobe/function/utilize/sequence/interprete is Prediction says phishing URL *************************
ERROR:cassandra.datastax.cloud:HTTP Error 401: Unauthorized
Traceback (most recent call last):
  File "/tmp/8dc9524939e911d/antenv/lib/python3.9/site-packages/cassandra/datastax/cloud/__init__.py", line 137, in read_metadata_info
    response = urlopen(url, context=config.ssl_context, timeout=timeout)
  File "/opt/python/3.9.19/lib/python3.9/urllib/request.py", line 214, in urlopen
    return opener.open(url, data, timeout)
  File "/opt/python/3.9.19/lib/python3.9/urllib/request.py", line 523, in open
    response = meth(req, response)
  File "/opt/python/3.9.19/lib/python3.9/urllib/request.py", line 632, in http_response
    response = self.parent.error(
  File "/opt/python/3.9.19/lib/python3.9/urllib/request.py", line 561, in error
    return self._call_chain(*args)
  File "/opt/python/3.9.19/lib/python3.9/urllib/request.py", line 494, in _call_chain
    result = func(*args)
  File "/opt/python/3.9.19/lib/python3.9/urllib/request.py", line 641, in http_error_default
    raise HTTPError(req.full_url, code, msg, hdrs, fp)
urllib.error.HTTPError: HTTP Error 401: Unauthorized
ERROR:app:*****************Database is not working*************************
INFO:app:*****************Prediction for URL started *************************
INFO:app:time_response 0.054975
INFO:app:domain_spf 0
INFO:app:asn_ip 1
INFO:app:time_domain_activation 27
INFO:app:time_domain_expiration 337
INFO:app:qty_ip_resolved 2
INFO:app:qty_nameservers 2
INFO:app:qty_mx_servers None
INFO:app:ttl_hostname 1
INFO:app:tls_ssl_certificate 1
INFO:app:qty_redirects 0
INFO:app:url_google_index 1
INFO:app:domain_google_index 0
INFO:app:url_shortened 0
INFO:app:Domain: biidingrfponlinedoucuments.click
INFO:app:URL: https://biidingrfponlinedoucuments.click/rfp/rfq/requestforquoation/redundancy/adobe/function/utilize/sequence/interprete?__cf_chl_rt_tk=tQH1jvFhKojQCAH7jUMllYkcRrRO7Dia1lpOgq3Q9rA-1719838024-0.0.1.1-4265
INFO:app:*****************Prediction for https://biidingrfponlinedoucuments.click/rfp/rfq/requestforquoation/redundancy/adobe/function/utilize/sequence/interprete?__cf_chl_rt_tk=tQH1jvFhKojQCAH7jUMllYkcRrRO7Dia1lpOgq3Q9rA-1719838024-0.0.1.1-4265 is Prediction says phishing URL *************************
ERROR:cassandra.datastax.cloud:HTTP Error 401: Unauthorized
Traceback (most recent call last):
  File "/tmp/8dc9524939e911d/antenv/lib/python3.9/site-packages/cassandra/datastax/cloud/__init__.py", line 137, in read_metadata_info
    response = urlopen(url, context=config.ssl_context, timeout=timeout)
  File "/opt/python/3.9.19/lib/python3.9/urllib/request.py", line 214, in urlopen
    return opener.open(url, data, timeout)
  File "/opt/python/3.9.19/lib/python3.9/urllib/request.py", line 523, in open
    response = meth(req, response)
  File "/opt/python/3.9.19/lib/python3.9/urllib/request.py", line 632, in http_response
    response = self.parent.error(
  File "/opt/python/3.9.19/lib/python3.9/urllib/request.py", line 561, in error
    return self._call_chain(*args)
  File "/opt/python/3.9.19/lib/python3.9/urllib/request.py", line 494, in _call_chain
    result = func(*args)
  File "/opt/python/3.9.19/lib/python3.9/urllib/request.py", line 641, in http_error_default
    raise HTTPError(req.full_url, code, msg, hdrs, fp)
urllib.error.HTTPError: HTTP Error 401: Unauthorized
ERROR:app:*****************Database is not working*************************
INFO:app:*****************Prediction for URL started *************************
INFO:app:time_response 0.068608
INFO:app:domain_spf 0
INFO:app:asn_ip 1
INFO:app:time_domain_activation 0
INFO:app:time_domain_expiration 0
INFO:app:qty_ip_resolved 2
INFO:app:qty_nameservers None
INFO:app:qty_mx_servers None
INFO:app:ttl_hostname 7
INFO:app:tls_ssl_certificate 1
INFO:app:qty_redirects 0
INFO:app:url_google_index 1
INFO:app:domain_google_index 0
INFO:app:url_shortened 0
INFO:app:Domain: phishr.vercel.app
INFO:app:URL: https://phishr.vercel.app/
INFO:app:*****************Prediction for https://phishr.vercel.app/ is Prediction says safe browsing URL *************************
ERROR:cassandra.datastax.cloud:HTTP Error 401: Unauthorized
Traceback (most recent call last):
  File "/tmp/8dc9524939e911d/antenv/lib/python3.9/site-packages/cassandra/datastax/cloud/__init__.py", line 137, in read_metadata_info
    response = urlopen(url, context=config.ssl_context, timeout=timeout)
  File "/opt/python/3.9.19/lib/python3.9/urllib/request.py", line 214, in urlopen
    return opener.open(url, data, timeout)
  File "/opt/python/3.9.19/lib/python3.9/urllib/request.py", line 523, in open
    response = meth(req, response)
  File "/opt/python/3.9.19/lib/python3.9/urllib/request.py", line 632, in http_response
    response = self.parent.error(
  File "/opt/python/3.9.19/lib/python3.9/urllib/request.py", line 561, in error
    return self._call_chain(*args)
  File "/opt/python/3.9.19/lib/python3.9/urllib/request.py", line 494, in _call_chain
    result = func(*args)
  File "/opt/python/3.9.19/lib/python3.9/urllib/request.py", line 641, in http_error_default
    raise HTTPError(req.full_url, code, msg, hdrs, fp)
urllib.error.HTTPError: HTTP Error 401: Unauthorized
ERROR:app:*****************Database is not working*************************
INFO:app:*****************Prediction opening *************************
INFO:app:*****************Prediction opening *************************
