DEBUG:appServiceAppLogs:Waiting for the logs flag to be set
INFO:appsvc_profiler.installer:Code Profiler Installer is starting up
INFO:appsvc_profiler.installer:Cleaning up any existing status file which indicated signal handlers initialized status
INFO:appsvc_profiler.installer:Attempting to delete the signal_handler status file for instance id 2d174a675073b04c10860aed8bc9c85d3c0490d7a18f148eaba7e8c0e62eca31
INFO:appsvc_profiler.installer:successfully deleted the status file
DEBUG:appsvc_profiler.installer:APPSETTING_WEBSITE_ENABLE_DEFAULT_CODE_PROFILER : None
INFO:appsvc_profiler.installer:Attempting to install the default code profiler.
DEBUG:appsvc_profiler.installer:viztracer would save traces to /tmp/2d174a_profiler_trace.json
INFO:appsvc_profiler.installer:Successfully installed code profiler.
INFO:appsvc_profiler.installer:Signal Handlers SIGUSR for needed code-profiler have been initialized for gunicorn process on instance 2d174a675073b04c10860aed8bc9c85d3c0490d7a18f148eaba7e8c0e62eca31
DEBUG:appsvc_profiler.installer:Code Profiler Installer is exiting as installation is completed
INFO:app:*****************Prediction opening *************************
INFO:app:*****************Prediction opening *************************
INFO:app:*****************Prediction opening *************************
INFO:app:*****************Prediction opening *************************
INFO:app:*****************Prediction opening *************************
WARNING:cassandra.cluster:Downgrading core protocol version from 66 to 65 for 74f3ea48-05df-4249-a12b-fac40645190d-us-east-1.db.astra.datastax.com:29042:0669df0f-031f-383e-b452-67a9679bbc6a. To avoid this, it is best practice to explicitly set Cluster(protocol_version) to the version supported by your cluster. http://datastax.github.io/python-driver/api/cassandra/cluster.html#cassandra.cluster.Cluster.protocol_version
WARNING:cassandra.cluster:Downgrading core protocol version from 65 to 5 for 74f3ea48-05df-4249-a12b-fac40645190d-us-east-1.db.astra.datastax.com:29042:0669df0f-031f-383e-b452-67a9679bbc6a. To avoid this, it is best practice to explicitly set Cluster(protocol_version) to the version supported by your cluster. http://datastax.github.io/python-driver/api/cassandra/cluster.html#cassandra.cluster.Cluster.protocol_version
WARNING:cassandra.cluster:Downgrading core protocol version from 5 to 4 for 74f3ea48-05df-4249-a12b-fac40645190d-us-east-1.db.astra.datastax.com:29042:0669df0f-031f-383e-b452-67a9679bbc6a. To avoid this, it is best practice to explicitly set Cluster(protocol_version) to the version supported by your cluster. http://datastax.github.io/python-driver/api/cassandra/cluster.html#cassandra.cluster.Cluster.protocol_version
INFO:cassandra.policies:Using datacenter 'us-east-1' for DCAwareRoundRobinPolicy (via host '74f3ea48-05df-4249-a12b-fac40645190d-us-east-1.db.astra.datastax.com:29042:0669df0f-031f-383e-b452-67a9679bbc6a'); if incorrect, please specify a local_dc to the constructor, or limit contact points to local cluster nodes
WARNING:cassandra.cluster:Found multiple hosts with the same endpoint (74f3ea48-05df-4249-a12b-fac40645190d-us-east-1.db.astra.datastax.com:29042:0669df0f-031f-383e-b452-67a9679bbc6a). Excluding peer 10.0.0.5
INFO:cassandra.cluster:Cassandra host 74f3ea48-05df-4249-a12b-fac40645190d-us-east-1.db.astra.datastax.com:29042:00694036-11ec-39fb-8238-d79afd9b0e46 removed
INFO:app:*****************Prediction opening *************************
INFO:app:*****************Prediction opening *************************
INFO:app:*****************Prediction opening *************************
INFO:app:*****************Prediction opening *************************
WARNING:cassandra.cluster:Downgrading core protocol version from 66 to 65 for 74f3ea48-05df-4249-a12b-fac40645190d-us-east-1.db.astra.datastax.com:29042:0669df0f-031f-383e-b452-67a9679bbc6a. To avoid this, it is best practice to explicitly set Cluster(protocol_version) to the version supported by your cluster. http://datastax.github.io/python-driver/api/cassandra/cluster.html#cassandra.cluster.Cluster.protocol_version
WARNING:cassandra.cluster:Downgrading core protocol version from 65 to 5 for 74f3ea48-05df-4249-a12b-fac40645190d-us-east-1.db.astra.datastax.com:29042:0669df0f-031f-383e-b452-67a9679bbc6a. To avoid this, it is best practice to explicitly set Cluster(protocol_version) to the version supported by your cluster. http://datastax.github.io/python-driver/api/cassandra/cluster.html#cassandra.cluster.Cluster.protocol_version
WARNING:cassandra.cluster:Downgrading core protocol version from 5 to 4 for 74f3ea48-05df-4249-a12b-fac40645190d-us-east-1.db.astra.datastax.com:29042:0669df0f-031f-383e-b452-67a9679bbc6a. To avoid this, it is best practice to explicitly set Cluster(protocol_version) to the version supported by your cluster. http://datastax.github.io/python-driver/api/cassandra/cluster.html#cassandra.cluster.Cluster.protocol_version
INFO:cassandra.policies:Using datacenter 'us-east-1' for DCAwareRoundRobinPolicy (via host '74f3ea48-05df-4249-a12b-fac40645190d-us-east-1.db.astra.datastax.com:29042:0669df0f-031f-383e-b452-67a9679bbc6a'); if incorrect, please specify a local_dc to the constructor, or limit contact points to local cluster nodes
WARNING:cassandra.cluster:Found multiple hosts with the same endpoint (74f3ea48-05df-4249-a12b-fac40645190d-us-east-1.db.astra.datastax.com:29042:0669df0f-031f-383e-b452-67a9679bbc6a). Excluding peer 10.0.0.5
INFO:cassandra.cluster:Cassandra host 74f3ea48-05df-4249-a12b-fac40645190d-us-east-1.db.astra.datastax.com:29042:00694036-11ec-39fb-8238-d79afd9b0e46 removed
INFO:app:*****************Prediction opening *************************
INFO:app:*****************Prediction opening *************************
INFO:app:*****************Prediction opening *************************
INFO:app:*****************Prediction opening *************************
INFO:app:*****************Prediction opening *************************
ERROR:cassandra.datastax.cloud:HTTP Error 401: Unauthorized
Traceback (most recent call last):
  File "/tmp/8dc9524939e911d/antenv/lib/python3.9/site-packages/cassandra/datastax/cloud/__init__.py", line 137, in read_metadata_info
    response = urlopen(url, context=config.ssl_context, timeout=timeout)
  File "/opt/python/3.9.18/lib/python3.9/urllib/request.py", line 214, in urlopen
    return opener.open(url, data, timeout)
  File "/opt/python/3.9.18/lib/python3.9/urllib/request.py", line 523, in open
    response = meth(req, response)
  File "/opt/python/3.9.18/lib/python3.9/urllib/request.py", line 632, in http_response
    response = self.parent.error(
  File "/opt/python/3.9.18/lib/python3.9/urllib/request.py", line 561, in error
    return self._call_chain(*args)
  File "/opt/python/3.9.18/lib/python3.9/urllib/request.py", line 494, in _call_chain
    result = func(*args)
  File "/opt/python/3.9.18/lib/python3.9/urllib/request.py", line 641, in http_error_default
    raise HTTPError(req.full_url, code, msg, hdrs, fp)
urllib.error.HTTPError: HTTP Error 401: Unauthorized
INFO:app:*****************Prediction opening *************************
INFO:app:*****************Prediction for URL started *************************
INFO:app:time_response 0.092192
INFO:app:domain_spf 0
INFO:app:asn_ip 1
INFO:app:time_domain_activation 7074
INFO:app:time_domain_expiration 230
INFO:app:qty_ip_resolved 16
INFO:app:qty_nameservers None
INFO:app:qty_mx_servers None
INFO:app:ttl_hostname 1
INFO:app:tls_ssl_certificate 1
INFO:app:qty_redirects 0
INFO:app:url_google_index 0
INFO:app:domain_google_index 0
INFO:app:url_shortened 0
INFO:app:Domain: www.youtube.com
INFO:app:URL: https://www.youtube.com/results?search_query=speech+dataprocessing
INFO:app:*****************Prediction for https://www.youtube.com/results?search_query=speech+dataprocessing is Prediction says safe browsing URL *************************
ERROR:cassandra.datastax.cloud:HTTP Error 401: Unauthorized
Traceback (most recent call last):
  File "/tmp/8dc9524939e911d/antenv/lib/python3.9/site-packages/cassandra/datastax/cloud/__init__.py", line 137, in read_metadata_info
    response = urlopen(url, context=config.ssl_context, timeout=timeout)
  File "/opt/python/3.9.18/lib/python3.9/urllib/request.py", line 214, in urlopen
    return opener.open(url, data, timeout)
  File "/opt/python/3.9.18/lib/python3.9/urllib/request.py", line 523, in open
    response = meth(req, response)
  File "/opt/python/3.9.18/lib/python3.9/urllib/request.py", line 632, in http_response
    response = self.parent.error(
  File "/opt/python/3.9.18/lib/python3.9/urllib/request.py", line 561, in error
    return self._call_chain(*args)
  File "/opt/python/3.9.18/lib/python3.9/urllib/request.py", line 494, in _call_chain
    result = func(*args)
  File "/opt/python/3.9.18/lib/python3.9/urllib/request.py", line 641, in http_error_default
    raise HTTPError(req.full_url, code, msg, hdrs, fp)
urllib.error.HTTPError: HTTP Error 401: Unauthorized
ERROR:app:*****************Database is not working*************************
INFO:app:*****************Prediction opening *************************
ERROR:cassandra.datastax.cloud:<urlopen error _ssl.c:1112: The handshake operation timed out>
Traceback (most recent call last):
  File "/opt/python/3.9.18/lib/python3.9/urllib/request.py", line 1346, in do_open
    h.request(req.get_method(), req.selector, req.data, headers,
  File "/opt/python/3.9.18/lib/python3.9/http/client.py", line 1285, in request
    self._send_request(method, url, body, headers, encode_chunked)
  File "/opt/python/3.9.18/lib/python3.9/http/client.py", line 1331, in _send_request
    self.endheaders(body, encode_chunked=encode_chunked)
  File "/opt/python/3.9.18/lib/python3.9/http/client.py", line 1280, in endheaders
    self._send_output(message_body, encode_chunked=encode_chunked)
  File "/opt/python/3.9.18/lib/python3.9/http/client.py", line 1040, in _send_output
    self.send(msg)
  File "/opt/python/3.9.18/lib/python3.9/http/client.py", line 980, in send
    self.connect()
  File "/opt/python/3.9.18/lib/python3.9/http/client.py", line 1454, in connect
    self.sock = self._context.wrap_socket(self.sock,
  File "/opt/python/3.9.18/lib/python3.9/ssl.py", line 501, in wrap_socket
    return self.sslsocket_class._create(
  File "/opt/python/3.9.18/lib/python3.9/ssl.py", line 1074, in _create
    self.do_handshake()
  File "/opt/python/3.9.18/lib/python3.9/ssl.py", line 1343, in do_handshake
    self._sslobj.do_handshake()
socket.timeout: _ssl.c:1112: The handshake operation timed out

During handling of the above exception, another exception occurred:

Traceback (most recent call last):
  File "/tmp/8dc9524939e911d/antenv/lib/python3.9/site-packages/cassandra/datastax/cloud/__init__.py", line 137, in read_metadata_info
    response = urlopen(url, context=config.ssl_context, timeout=timeout)
  File "/opt/python/3.9.18/lib/python3.9/urllib/request.py", line 214, in urlopen
    return opener.open(url, data, timeout)
  File "/opt/python/3.9.18/lib/python3.9/urllib/request.py", line 517, in open
    response = self._open(req, data)
  File "/opt/python/3.9.18/lib/python3.9/urllib/request.py", line 534, in _open
    result = self._call_chain(self.handle_open, protocol, protocol +
  File "/opt/python/3.9.18/lib/python3.9/urllib/request.py", line 494, in _call_chain
    result = func(*args)
  File "/opt/python/3.9.18/lib/python3.9/urllib/request.py", line 1389, in https_open
    return self.do_open(http.client.HTTPSConnection, req,
  File "/opt/python/3.9.18/lib/python3.9/urllib/request.py", line 1349, in do_open
    raise URLError(err)
urllib.error.URLError: <urlopen error _ssl.c:1112: The handshake operation timed out>
INFO:app:*****************Prediction opening *************************
