INFO:appsvc_profiler.installer:Code Profiler Installer is starting up
INFO:appsvc_profiler.installer:Cleaning up any existing status file which indicated signal handlers initialized status
INFO:appsvc_profiler.installer:Attempting to delete the signal_handler status file for instance id 1e94db65c56587b74b0d8f52a80aa0a2a9a213bd6f66e280ee4d42652e7c2bc0
INFO:appsvc_profiler.installer:successfully deleted the status file
DEBUG:appsvc_profiler.installer:APPSETTING_WEBSITE_ENABLE_DEFAULT_CODE_PROFILER : None
INFO:appsvc_profiler.installer:Attempting to install the default code profiler.
DEBUG:appsvc_profiler.installer:viztracer would save traces to /tmp/1e94db_profiler_trace.json
INFO:appsvc_profiler.installer:Successfully installed code profiler.
INFO:appsvc_profiler.installer:Signal Handlers SIGUSR for needed code-profiler have been initialized for gunicorn process on instance 1e94db65c56587b74b0d8f52a80aa0a2a9a213bd6f66e280ee4d42652e7c2bc0
DEBUG:appsvc_profiler.installer:Code Profiler Installer is exiting as installation is completed
INFO:app:*****************Prediction opening *************************
INFO:app:*****************Prediction opening *************************
INFO:app:*****************Prediction opening *************************
ERROR:cassandra.datastax.cloud:HTTP Error 401: Unauthorized
Traceback (most recent call last):
  File "/tmp/8dc9524939e911d/antenv/lib/python3.9/site-packages/cassandra/datastax/cloud/__init__.py", line 137, in read_metadata_info
    response = urlopen(url, context=config.ssl_context, timeout=timeout)
  File "/opt/python/3.9.19/lib/python3.9/urllib/request.py", line 214, in urlopen
    return opener.open(url, data, timeout)
  File "/opt/python/3.9.19/lib/python3.9/urllib/request.py", line 523, in open
    response = meth(req, response)
  File "/opt/python/3.9.19/lib/python3.9/urllib/request.py", line 632, in http_response
    response = self.parent.error(
  File "/opt/python/3.9.19/lib/python3.9/urllib/request.py", line 561, in error
    return self._call_chain(*args)
  File "/opt/python/3.9.19/lib/python3.9/urllib/request.py", line 494, in _call_chain
    result = func(*args)
  File "/opt/python/3.9.19/lib/python3.9/urllib/request.py", line 641, in http_error_default
    raise HTTPError(req.full_url, code, msg, hdrs, fp)
urllib.error.HTTPError: HTTP Error 401: Unauthorized
INFO:app:*****************Prediction opening *************************
ERROR:app:Exception on / [HEAD]
Traceback (most recent call last):
  File "/tmp/8dc9524939e911d/antenv/lib/python3.9/site-packages/flask/app.py", line 1463, in wsgi_app
    response = self.full_dispatch_request()
  File "/tmp/8dc9524939e911d/antenv/lib/python3.9/site-packages/flask/app.py", line 873, in full_dispatch_request
    return self.finalize_request(rv)
  File "/tmp/8dc9524939e911d/antenv/lib/python3.9/site-packages/flask/app.py", line 892, in finalize_request
    response = self.make_response(rv)
  File "/tmp/8dc9524939e911d/antenv/lib/python3.9/site-packages/flask/app.py", line 1164, in make_response
    raise TypeError(
TypeError: The view function for 'predictui' did not return a valid response. The function either returned None or ended without a return statement.
INFO:app:*****************Prediction opening *************************
