DEBUG:appServiceAppLogs:Waiting for the logs flag to be set
INFO:appsvc_profiler.installer:Code Profiler Installer is starting up
INFO:appsvc_profiler.installer:Cleaning up any existing status file which indicated signal handlers initialized status
INFO:appsvc_profiler.installer:Attempting to delete the signal_handler status file for instance id bcf44d659ba300c7830a43c66f543def03d4ae7e888c5d45ba7b064e17b52927
INFO:appsvc_profiler.installer:successfully deleted the status file
DEBUG:appsvc_profiler.installer:APPSETTING_WEBSITE_ENABLE_DEFAULT_CODE_PROFILER : None
INFO:appsvc_profiler.installer:Attempting to install the default code profiler.
DEBUG:appsvc_profiler.installer:viztracer would save traces to /tmp/bcf44d_profiler_trace.json
INFO:appsvc_profiler.installer:Successfully installed code profiler.
INFO:appsvc_profiler.installer:Signal Handlers SIGUSR for needed code-profiler have been initialized for gunicorn process on instance bcf44d659ba300c7830a43c66f543def03d4ae7e888c5d45ba7b064e17b52927
DEBUG:appsvc_profiler.installer:Code Profiler Installer is exiting as installation is completed
INFO:app:*****************Prediction opening *************************
INFO:app:*****************Prediction opening *************************
ERROR:cassandra.datastax.cloud:HTTP Error 401: Unauthorized
Traceback (most recent call last):
  File "/tmp/8dc9524939e911d/antenv/lib/python3.9/site-packages/cassandra/datastax/cloud/__init__.py", line 137, in read_metadata_info
    response = urlopen(url, context=config.ssl_context, timeout=timeout)
  File "/opt/python/3.9.19/lib/python3.9/urllib/request.py", line 214, in urlopen
    return opener.open(url, data, timeout)
  File "/opt/python/3.9.19/lib/python3.9/urllib/request.py", line 523, in open
    response = meth(req, response)
  File "/opt/python/3.9.19/lib/python3.9/urllib/request.py", line 632, in http_response
    response = self.parent.error(
  File "/opt/python/3.9.19/lib/python3.9/urllib/request.py", line 561, in error
    return self._call_chain(*args)
  File "/opt/python/3.9.19/lib/python3.9/urllib/request.py", line 494, in _call_chain
    result = func(*args)
  File "/opt/python/3.9.19/lib/python3.9/urllib/request.py", line 641, in http_error_default
    raise HTTPError(req.full_url, code, msg, hdrs, fp)
urllib.error.HTTPError: HTTP Error 401: Unauthorized
INFO:app:*****************Prediction opening *************************
INFO:app:*****************Prediction opening *************************
INFO:app:*****************Prediction opening *************************
INFO:app:*****************Prediction for URL started *************************
INFO:app:time_response 0.397135
INFO:app:domain_spf 0
INFO:app:asn_ip 1
INFO:app:time_domain_activation 9851
INFO:app:time_domain_expiration 1470
INFO:app:qty_ip_resolved 6
INFO:app:qty_nameservers None
INFO:app:qty_mx_servers 5
INFO:app:ttl_hostname 1
INFO:app:tls_ssl_certificate 1
INFO:app:qty_redirects 0
INFO:app:url_google_index 1
INFO:app:domain_google_index 0
INFO:app:url_shortened 0
INFO:app:Domain: drive.google.com
INFO:app:URL: https://drive.google.com/file/d/1uDBbSpj3qAV8HxUXb3Iu_k_yAFyfzq6r/view
INFO:app:*****************Prediction for https://drive.google.com/file/d/1uDBbSpj3qAV8HxUXb3Iu_k_yAFyfzq6r/view is Prediction says safe browsing URL *************************
ERROR:cassandra.datastax.cloud:HTTP Error 401: Unauthorized
Traceback (most recent call last):
  File "/tmp/8dc9524939e911d/antenv/lib/python3.9/site-packages/cassandra/datastax/cloud/__init__.py", line 137, in read_metadata_info
    response = urlopen(url, context=config.ssl_context, timeout=timeout)
  File "/opt/python/3.9.19/lib/python3.9/urllib/request.py", line 214, in urlopen
    return opener.open(url, data, timeout)
  File "/opt/python/3.9.19/lib/python3.9/urllib/request.py", line 523, in open
    response = meth(req, response)
  File "/opt/python/3.9.19/lib/python3.9/urllib/request.py", line 632, in http_response
    response = self.parent.error(
  File "/opt/python/3.9.19/lib/python3.9/urllib/request.py", line 561, in error
    return self._call_chain(*args)
  File "/opt/python/3.9.19/lib/python3.9/urllib/request.py", line 494, in _call_chain
    result = func(*args)
  File "/opt/python/3.9.19/lib/python3.9/urllib/request.py", line 641, in http_error_default
    raise HTTPError(req.full_url, code, msg, hdrs, fp)
urllib.error.HTTPError: HTTP Error 401: Unauthorized
ERROR:app:*****************Database is not working*************************
INFO:app:*****************Prediction opening *************************
ERROR:cassandra.datastax.cloud:HTTP Error 401: Unauthorized
Traceback (most recent call last):
  File "/tmp/8dc9524939e911d/antenv/lib/python3.9/site-packages/cassandra/datastax/cloud/__init__.py", line 137, in read_metadata_info
    response = urlopen(url, context=config.ssl_context, timeout=timeout)
  File "/opt/python/3.9.19/lib/python3.9/urllib/request.py", line 214, in urlopen
    return opener.open(url, data, timeout)
  File "/opt/python/3.9.19/lib/python3.9/urllib/request.py", line 523, in open
    response = meth(req, response)
  File "/opt/python/3.9.19/lib/python3.9/urllib/request.py", line 632, in http_response
    response = self.parent.error(
  File "/opt/python/3.9.19/lib/python3.9/urllib/request.py", line 561, in error
    return self._call_chain(*args)
  File "/opt/python/3.9.19/lib/python3.9/urllib/request.py", line 494, in _call_chain
    result = func(*args)
  File "/opt/python/3.9.19/lib/python3.9/urllib/request.py", line 641, in http_error_default
    raise HTTPError(req.full_url, code, msg, hdrs, fp)
urllib.error.HTTPError: HTTP Error 401: Unauthorized
ERROR:cassandra.datastax.cloud:HTTP Error 401: Unauthorized
Traceback (most recent call last):
  File "/tmp/8dc9524939e911d/antenv/lib/python3.9/site-packages/cassandra/datastax/cloud/__init__.py", line 137, in read_metadata_info
    response = urlopen(url, context=config.ssl_context, timeout=timeout)
  File "/opt/python/3.9.19/lib/python3.9/urllib/request.py", line 214, in urlopen
    return opener.open(url, data, timeout)
  File "/opt/python/3.9.19/lib/python3.9/urllib/request.py", line 523, in open
    response = meth(req, response)
  File "/opt/python/3.9.19/lib/python3.9/urllib/request.py", line 632, in http_response
    response = self.parent.error(
  File "/opt/python/3.9.19/lib/python3.9/urllib/request.py", line 561, in error
    return self._call_chain(*args)
  File "/opt/python/3.9.19/lib/python3.9/urllib/request.py", line 494, in _call_chain
    result = func(*args)
  File "/opt/python/3.9.19/lib/python3.9/urllib/request.py", line 641, in http_error_default
    raise HTTPError(req.full_url, code, msg, hdrs, fp)
urllib.error.HTTPError: HTTP Error 401: Unauthorized
INFO:app:*****************Prediction opening *************************
INFO:app:*****************Prediction opening *************************
ERROR:cassandra.datastax.cloud:HTTP Error 401: Unauthorized
Traceback (most recent call last):
  File "/tmp/8dc9524939e911d/antenv/lib/python3.9/site-packages/cassandra/datastax/cloud/__init__.py", line 137, in read_metadata_info
    response = urlopen(url, context=config.ssl_context, timeout=timeout)
  File "/opt/python/3.9.19/lib/python3.9/urllib/request.py", line 214, in urlopen
    return opener.open(url, data, timeout)
  File "/opt/python/3.9.19/lib/python3.9/urllib/request.py", line 523, in open
    response = meth(req, response)
  File "/opt/python/3.9.19/lib/python3.9/urllib/request.py", line 632, in http_response
    response = self.parent.error(
  File "/opt/python/3.9.19/lib/python3.9/urllib/request.py", line 561, in error
    return self._call_chain(*args)
  File "/opt/python/3.9.19/lib/python3.9/urllib/request.py", line 494, in _call_chain
    result = func(*args)
  File "/opt/python/3.9.19/lib/python3.9/urllib/request.py", line 641, in http_error_default
    raise HTTPError(req.full_url, code, msg, hdrs, fp)
urllib.error.HTTPError: HTTP Error 401: Unauthorized
ERROR:cassandra.datastax.cloud:HTTP Error 401: Unauthorized
Traceback (most recent call last):
  File "/tmp/8dc9524939e911d/antenv/lib/python3.9/site-packages/cassandra/datastax/cloud/__init__.py", line 137, in read_metadata_info
    response = urlopen(url, context=config.ssl_context, timeout=timeout)
  File "/opt/python/3.9.19/lib/python3.9/urllib/request.py", line 214, in urlopen
    return opener.open(url, data, timeout)
  File "/opt/python/3.9.19/lib/python3.9/urllib/request.py", line 523, in open
    response = meth(req, response)
  File "/opt/python/3.9.19/lib/python3.9/urllib/request.py", line 632, in http_response
    response = self.parent.error(
  File "/opt/python/3.9.19/lib/python3.9/urllib/request.py", line 561, in error
    return self._call_chain(*args)
  File "/opt/python/3.9.19/lib/python3.9/urllib/request.py", line 494, in _call_chain
    result = func(*args)
  File "/opt/python/3.9.19/lib/python3.9/urllib/request.py", line 641, in http_error_default
    raise HTTPError(req.full_url, code, msg, hdrs, fp)
urllib.error.HTTPError: HTTP Error 401: Unauthorized
ERROR:app:Exception on /fetch [GET]
Traceback (most recent call last):
  File "/tmp/8dc9524939e911d/antenv/lib/python3.9/site-packages/cassandra/datastax/cloud/__init__.py", line 137, in read_metadata_info
    response = urlopen(url, context=config.ssl_context, timeout=timeout)
  File "/opt/python/3.9.19/lib/python3.9/urllib/request.py", line 214, in urlopen
    return opener.open(url, data, timeout)
  File "/opt/python/3.9.19/lib/python3.9/urllib/request.py", line 523, in open
    response = meth(req, response)
  File "/opt/python/3.9.19/lib/python3.9/urllib/request.py", line 632, in http_response
    response = self.parent.error(
  File "/opt/python/3.9.19/lib/python3.9/urllib/request.py", line 561, in error
    return self._call_chain(*args)
  File "/opt/python/3.9.19/lib/python3.9/urllib/request.py", line 494, in _call_chain
    result = func(*args)
  File "/opt/python/3.9.19/lib/python3.9/urllib/request.py", line 641, in http_error_default
    raise HTTPError(req.full_url, code, msg, hdrs, fp)
urllib.error.HTTPError: HTTP Error 401: Unauthorized

During handling of the above exception, another exception occurred:

Traceback (most recent call last):
  File "/tmp/8dc9524939e911d/antenv/lib/python3.9/site-packages/flask/app.py", line 1463, in wsgi_app
    response = self.full_dispatch_request()
  File "/tmp/8dc9524939e911d/antenv/lib/python3.9/site-packages/flask/app.py", line 872, in full_dispatch_request
    rv = self.handle_user_exception(e)
  File "/tmp/8dc9524939e911d/antenv/lib/python3.9/site-packages/flask/app.py", line 870, in full_dispatch_request
    rv = self.dispatch_request()
  File "/tmp/8dc9524939e911d/antenv/lib/python3.9/site-packages/flask/app.py", line 855, in dispatch_request
    return self.ensure_sync(self.view_functions[rule.endpoint])(**view_args)  # type: ignore[no-any-return]
  File "/tmp/8dc9524939e911d/app.py", line 66, in fetch
    all_entries = fetch_all_entries()
  File "/tmp/8dc9524939e911d/connect_database.py", line 60, in fetch_all_entries
    cluster, session = connect_to_cassandra()
  File "/tmp/8dc9524939e911d/connect_database.py", line 24, in connect_to_cassandra
    cluster = Cluster(cloud=cloud_config, auth_provider=auth_provider)
  File "cassandra/cluster.py", line 1172, in cassandra.cluster.Cluster.__init__
  File "/tmp/8dc9524939e911d/antenv/lib/python3.9/site-packages/cassandra/datastax/cloud/__init__.py", line 91, in get_cloud_config
    config = read_metadata_info(config, cloud_config)
  File "/tmp/8dc9524939e911d/antenv/lib/python3.9/site-packages/cassandra/datastax/cloud/__init__.py", line 140, in read_metadata_info
    raise DriverException("Unable to connect to the metadata service at %s. "
cassandra.DriverException: Unable to connect to the metadata service at https://74f3ea48-05df-4249-a12b-fac40645190d-us-east-1.db.astra.datastax.com:29080/metadata. Check the cluster status in the cloud console. 
INFO:app:*****************Prediction opening *************************
ERROR:cassandra.datastax.cloud:HTTP Error 401: Unauthorized
Traceback (most recent call last):
  File "/tmp/8dc9524939e911d/antenv/lib/python3.9/site-packages/cassandra/datastax/cloud/__init__.py", line 137, in read_metadata_info
    response = urlopen(url, context=config.ssl_context, timeout=timeout)
  File "/opt/python/3.9.19/lib/python3.9/urllib/request.py", line 214, in urlopen
    return opener.open(url, data, timeout)
  File "/opt/python/3.9.19/lib/python3.9/urllib/request.py", line 523, in open
    response = meth(req, response)
  File "/opt/python/3.9.19/lib/python3.9/urllib/request.py", line 632, in http_response
    response = self.parent.error(
  File "/opt/python/3.9.19/lib/python3.9/urllib/request.py", line 561, in error
    return self._call_chain(*args)
  File "/opt/python/3.9.19/lib/python3.9/urllib/request.py", line 494, in _call_chain
    result = func(*args)
  File "/opt/python/3.9.19/lib/python3.9/urllib/request.py", line 641, in http_error_default
    raise HTTPError(req.full_url, code, msg, hdrs, fp)
urllib.error.HTTPError: HTTP Error 401: Unauthorized
ERROR:app:Exception on /fetch [GET]
Traceback (most recent call last):
  File "/tmp/8dc9524939e911d/antenv/lib/python3.9/site-packages/cassandra/datastax/cloud/__init__.py", line 137, in read_metadata_info
    response = urlopen(url, context=config.ssl_context, timeout=timeout)
  File "/opt/python/3.9.19/lib/python3.9/urllib/request.py", line 214, in urlopen
    return opener.open(url, data, timeout)
  File "/opt/python/3.9.19/lib/python3.9/urllib/request.py", line 523, in open
    response = meth(req, response)
  File "/opt/python/3.9.19/lib/python3.9/urllib/request.py", line 632, in http_response
    response = self.parent.error(
  File "/opt/python/3.9.19/lib/python3.9/urllib/request.py", line 561, in error
    return self._call_chain(*args)
  File "/opt/python/3.9.19/lib/python3.9/urllib/request.py", line 494, in _call_chain
    result = func(*args)
  File "/opt/python/3.9.19/lib/python3.9/urllib/request.py", line 641, in http_error_default
    raise HTTPError(req.full_url, code, msg, hdrs, fp)
urllib.error.HTTPError: HTTP Error 401: Unauthorized

During handling of the above exception, another exception occurred:

Traceback (most recent call last):
  File "/tmp/8dc9524939e911d/antenv/lib/python3.9/site-packages/flask/app.py", line 1463, in wsgi_app
    response = self.full_dispatch_request()
  File "/tmp/8dc9524939e911d/antenv/lib/python3.9/site-packages/flask/app.py", line 872, in full_dispatch_request
    rv = self.handle_user_exception(e)
  File "/tmp/8dc9524939e911d/antenv/lib/python3.9/site-packages/flask/app.py", line 870, in full_dispatch_request
    rv = self.dispatch_request()
  File "/tmp/8dc9524939e911d/antenv/lib/python3.9/site-packages/flask/app.py", line 855, in dispatch_request
    return self.ensure_sync(self.view_functions[rule.endpoint])(**view_args)  # type: ignore[no-any-return]
  File "/tmp/8dc9524939e911d/app.py", line 66, in fetch
    all_entries = fetch_all_entries()
  File "/tmp/8dc9524939e911d/connect_database.py", line 60, in fetch_all_entries
    cluster, session = connect_to_cassandra()
  File "/tmp/8dc9524939e911d/connect_database.py", line 24, in connect_to_cassandra
    cluster = Cluster(cloud=cloud_config, auth_provider=auth_provider)
  File "cassandra/cluster.py", line 1172, in cassandra.cluster.Cluster.__init__
  File "/tmp/8dc9524939e911d/antenv/lib/python3.9/site-packages/cassandra/datastax/cloud/__init__.py", line 91, in get_cloud_config
    config = read_metadata_info(config, cloud_config)
  File "/tmp/8dc9524939e911d/antenv/lib/python3.9/site-packages/cassandra/datastax/cloud/__init__.py", line 140, in read_metadata_info
    raise DriverException("Unable to connect to the metadata service at %s. "
cassandra.DriverException: Unable to connect to the metadata service at https://74f3ea48-05df-4249-a12b-fac40645190d-us-east-1.db.astra.datastax.com:29080/metadata. Check the cluster status in the cloud console. 
ERROR:cassandra.datastax.cloud:HTTP Error 401: Unauthorized
Traceback (most recent call last):
  File "/tmp/8dc9524939e911d/antenv/lib/python3.9/site-packages/cassandra/datastax/cloud/__init__.py", line 137, in read_metadata_info
    response = urlopen(url, context=config.ssl_context, timeout=timeout)
  File "/opt/python/3.9.19/lib/python3.9/urllib/request.py", line 214, in urlopen
    return opener.open(url, data, timeout)
  File "/opt/python/3.9.19/lib/python3.9/urllib/request.py", line 523, in open
    response = meth(req, response)
  File "/opt/python/3.9.19/lib/python3.9/urllib/request.py", line 632, in http_response
    response = self.parent.error(
  File "/opt/python/3.9.19/lib/python3.9/urllib/request.py", line 561, in error
    return self._call_chain(*args)
  File "/opt/python/3.9.19/lib/python3.9/urllib/request.py", line 494, in _call_chain
    result = func(*args)
  File "/opt/python/3.9.19/lib/python3.9/urllib/request.py", line 641, in http_error_default
    raise HTTPError(req.full_url, code, msg, hdrs, fp)
urllib.error.HTTPError: HTTP Error 401: Unauthorized
ERROR:app:Exception on /fetch [GET]
Traceback (most recent call last):
  File "/tmp/8dc9524939e911d/antenv/lib/python3.9/site-packages/cassandra/datastax/cloud/__init__.py", line 137, in read_metadata_info
    response = urlopen(url, context=config.ssl_context, timeout=timeout)
  File "/opt/python/3.9.19/lib/python3.9/urllib/request.py", line 214, in urlopen
    return opener.open(url, data, timeout)
  File "/opt/python/3.9.19/lib/python3.9/urllib/request.py", line 523, in open
    response = meth(req, response)
  File "/opt/python/3.9.19/lib/python3.9/urllib/request.py", line 632, in http_response
    response = self.parent.error(
  File "/opt/python/3.9.19/lib/python3.9/urllib/request.py", line 561, in error
    return self._call_chain(*args)
  File "/opt/python/3.9.19/lib/python3.9/urllib/request.py", line 494, in _call_chain
    result = func(*args)
  File "/opt/python/3.9.19/lib/python3.9/urllib/request.py", line 641, in http_error_default
    raise HTTPError(req.full_url, code, msg, hdrs, fp)
urllib.error.HTTPError: HTTP Error 401: Unauthorized

During handling of the above exception, another exception occurred:

Traceback (most recent call last):
  File "/tmp/8dc9524939e911d/antenv/lib/python3.9/site-packages/flask/app.py", line 1463, in wsgi_app
    response = self.full_dispatch_request()
  File "/tmp/8dc9524939e911d/antenv/lib/python3.9/site-packages/flask/app.py", line 872, in full_dispatch_request
    rv = self.handle_user_exception(e)
  File "/tmp/8dc9524939e911d/antenv/lib/python3.9/site-packages/flask/app.py", line 870, in full_dispatch_request
    rv = self.dispatch_request()
  File "/tmp/8dc9524939e911d/antenv/lib/python3.9/site-packages/flask/app.py", line 855, in dispatch_request
    return self.ensure_sync(self.view_functions[rule.endpoint])(**view_args)  # type: ignore[no-any-return]
  File "/tmp/8dc9524939e911d/app.py", line 66, in fetch
    all_entries = fetch_all_entries()
  File "/tmp/8dc9524939e911d/connect_database.py", line 60, in fetch_all_entries
    cluster, session = connect_to_cassandra()
  File "/tmp/8dc9524939e911d/connect_database.py", line 24, in connect_to_cassandra
    cluster = Cluster(cloud=cloud_config, auth_provider=auth_provider)
  File "cassandra/cluster.py", line 1172, in cassandra.cluster.Cluster.__init__
  File "/tmp/8dc9524939e911d/antenv/lib/python3.9/site-packages/cassandra/datastax/cloud/__init__.py", line 91, in get_cloud_config
    config = read_metadata_info(config, cloud_config)
  File "/tmp/8dc9524939e911d/antenv/lib/python3.9/site-packages/cassandra/datastax/cloud/__init__.py", line 140, in read_metadata_info
    raise DriverException("Unable to connect to the metadata service at %s. "
cassandra.DriverException: Unable to connect to the metadata service at https://74f3ea48-05df-4249-a12b-fac40645190d-us-east-1.db.astra.datastax.com:29080/metadata. Check the cluster status in the cloud console. 
INFO:app:*****************Prediction opening *************************
INFO:app:*****************Prediction for URL started *************************
INFO:app:time_response 0.212136
INFO:app:domain_spf 0
INFO:app:asn_ip 1
INFO:app:time_domain_activation 7977
INFO:app:time_domain_expiration 58
INFO:app:qty_ip_resolved 1
INFO:app:qty_nameservers None
INFO:app:qty_mx_servers None
INFO:app:ttl_hostname 1
INFO:app:tls_ssl_certificate 1
INFO:app:qty_redirects 0
INFO:app:url_google_index 1
INFO:app:domain_google_index 0
INFO:app:url_shortened 0
INFO:app:Domain: www.linkedin.com
INFO:app:URL: https://www.linkedin.com/in/utkarsh-vataliya-a7a467210/
INFO:app:*****************Prediction for https://www.linkedin.com/in/utkarsh-vataliya-a7a467210/ is Prediction says safe browsing URL *************************
ERROR:cassandra.datastax.cloud:HTTP Error 401: Unauthorized
Traceback (most recent call last):
  File "/tmp/8dc9524939e911d/antenv/lib/python3.9/site-packages/cassandra/datastax/cloud/__init__.py", line 137, in read_metadata_info
    response = urlopen(url, context=config.ssl_context, timeout=timeout)
  File "/opt/python/3.9.19/lib/python3.9/urllib/request.py", line 214, in urlopen
    return opener.open(url, data, timeout)
  File "/opt/python/3.9.19/lib/python3.9/urllib/request.py", line 523, in open
    response = meth(req, response)
  File "/opt/python/3.9.19/lib/python3.9/urllib/request.py", line 632, in http_response
    response = self.parent.error(
  File "/opt/python/3.9.19/lib/python3.9/urllib/request.py", line 561, in error
    return self._call_chain(*args)
  File "/opt/python/3.9.19/lib/python3.9/urllib/request.py", line 494, in _call_chain
    result = func(*args)
  File "/opt/python/3.9.19/lib/python3.9/urllib/request.py", line 641, in http_error_default
    raise HTTPError(req.full_url, code, msg, hdrs, fp)
urllib.error.HTTPError: HTTP Error 401: Unauthorized
ERROR:app:*****************Database is not working*************************
INFO:app:*****************Prediction opening *************************
ERROR:cassandra.datastax.cloud:HTTP Error 401: Unauthorized
Traceback (most recent call last):
  File "/tmp/8dc9524939e911d/antenv/lib/python3.9/site-packages/cassandra/datastax/cloud/__init__.py", line 137, in read_metadata_info
    response = urlopen(url, context=config.ssl_context, timeout=timeout)
  File "/opt/python/3.9.19/lib/python3.9/urllib/request.py", line 214, in urlopen
    return opener.open(url, data, timeout)
  File "/opt/python/3.9.19/lib/python3.9/urllib/request.py", line 523, in open
    response = meth(req, response)
  File "/opt/python/3.9.19/lib/python3.9/urllib/request.py", line 632, in http_response
    response = self.parent.error(
  File "/opt/python/3.9.19/lib/python3.9/urllib/request.py", line 561, in error
    return self._call_chain(*args)
  File "/opt/python/3.9.19/lib/python3.9/urllib/request.py", line 494, in _call_chain
    result = func(*args)
  File "/opt/python/3.9.19/lib/python3.9/urllib/request.py", line 641, in http_error_default
    raise HTTPError(req.full_url, code, msg, hdrs, fp)
urllib.error.HTTPError: HTTP Error 401: Unauthorized
INFO:app:*****************Prediction opening *************************
ERROR:cassandra.datastax.cloud:HTTP Error 401: Unauthorized
Traceback (most recent call last):
  File "/tmp/8dc9524939e911d/antenv/lib/python3.9/site-packages/cassandra/datastax/cloud/__init__.py", line 137, in read_metadata_info
    response = urlopen(url, context=config.ssl_context, timeout=timeout)
  File "/opt/python/3.9.19/lib/python3.9/urllib/request.py", line 214, in urlopen
    return opener.open(url, data, timeout)
  File "/opt/python/3.9.19/lib/python3.9/urllib/request.py", line 523, in open
    response = meth(req, response)
  File "/opt/python/3.9.19/lib/python3.9/urllib/request.py", line 632, in http_response
    response = self.parent.error(
  File "/opt/python/3.9.19/lib/python3.9/urllib/request.py", line 561, in error
    return self._call_chain(*args)
  File "/opt/python/3.9.19/lib/python3.9/urllib/request.py", line 494, in _call_chain
    result = func(*args)
  File "/opt/python/3.9.19/lib/python3.9/urllib/request.py", line 641, in http_error_default
    raise HTTPError(req.full_url, code, msg, hdrs, fp)
urllib.error.HTTPError: HTTP Error 401: Unauthorized
ERROR:cassandra.datastax.cloud:HTTP Error 401: Unauthorized
Traceback (most recent call last):
  File "/tmp/8dc9524939e911d/antenv/lib/python3.9/site-packages/cassandra/datastax/cloud/__init__.py", line 137, in read_metadata_info
    response = urlopen(url, context=config.ssl_context, timeout=timeout)
  File "/opt/python/3.9.19/lib/python3.9/urllib/request.py", line 214, in urlopen
    return opener.open(url, data, timeout)
  File "/opt/python/3.9.19/lib/python3.9/urllib/request.py", line 523, in open
    response = meth(req, response)
  File "/opt/python/3.9.19/lib/python3.9/urllib/request.py", line 632, in http_response
    response = self.parent.error(
  File "/opt/python/3.9.19/lib/python3.9/urllib/request.py", line 561, in error
    return self._call_chain(*args)
  File "/opt/python/3.9.19/lib/python3.9/urllib/request.py", line 494, in _call_chain
    result = func(*args)
  File "/opt/python/3.9.19/lib/python3.9/urllib/request.py", line 641, in http_error_default
    raise HTTPError(req.full_url, code, msg, hdrs, fp)
urllib.error.HTTPError: HTTP Error 401: Unauthorized
ERROR:app:Exception on /fetch [GET]
Traceback (most recent call last):
  File "/tmp/8dc9524939e911d/antenv/lib/python3.9/site-packages/cassandra/datastax/cloud/__init__.py", line 137, in read_metadata_info
    response = urlopen(url, context=config.ssl_context, timeout=timeout)
  File "/opt/python/3.9.19/lib/python3.9/urllib/request.py", line 214, in urlopen
    return opener.open(url, data, timeout)
  File "/opt/python/3.9.19/lib/python3.9/urllib/request.py", line 523, in open
    response = meth(req, response)
  File "/opt/python/3.9.19/lib/python3.9/urllib/request.py", line 632, in http_response
    response = self.parent.error(
  File "/opt/python/3.9.19/lib/python3.9/urllib/request.py", line 561, in error
    return self._call_chain(*args)
  File "/opt/python/3.9.19/lib/python3.9/urllib/request.py", line 494, in _call_chain
    result = func(*args)
  File "/opt/python/3.9.19/lib/python3.9/urllib/request.py", line 641, in http_error_default
    raise HTTPError(req.full_url, code, msg, hdrs, fp)
urllib.error.HTTPError: HTTP Error 401: Unauthorized

During handling of the above exception, another exception occurred:

Traceback (most recent call last):
  File "/tmp/8dc9524939e911d/antenv/lib/python3.9/site-packages/flask/app.py", line 1463, in wsgi_app
    response = self.full_dispatch_request()
  File "/tmp/8dc9524939e911d/antenv/lib/python3.9/site-packages/flask/app.py", line 872, in full_dispatch_request
    rv = self.handle_user_exception(e)
  File "/tmp/8dc9524939e911d/antenv/lib/python3.9/site-packages/flask/app.py", line 870, in full_dispatch_request
    rv = self.dispatch_request()
  File "/tmp/8dc9524939e911d/antenv/lib/python3.9/site-packages/flask/app.py", line 855, in dispatch_request
    return self.ensure_sync(self.view_functions[rule.endpoint])(**view_args)  # type: ignore[no-any-return]
  File "/tmp/8dc9524939e911d/app.py", line 66, in fetch
    all_entries = fetch_all_entries()
  File "/tmp/8dc9524939e911d/connect_database.py", line 60, in fetch_all_entries
    cluster, session = connect_to_cassandra()
  File "/tmp/8dc9524939e911d/connect_database.py", line 24, in connect_to_cassandra
    cluster = Cluster(cloud=cloud_config, auth_provider=auth_provider)
  File "cassandra/cluster.py", line 1172, in cassandra.cluster.Cluster.__init__
  File "/tmp/8dc9524939e911d/antenv/lib/python3.9/site-packages/cassandra/datastax/cloud/__init__.py", line 91, in get_cloud_config
    config = read_metadata_info(config, cloud_config)
  File "/tmp/8dc9524939e911d/antenv/lib/python3.9/site-packages/cassandra/datastax/cloud/__init__.py", line 140, in read_metadata_info
    raise DriverException("Unable to connect to the metadata service at %s. "
cassandra.DriverException: Unable to connect to the metadata service at https://74f3ea48-05df-4249-a12b-fac40645190d-us-east-1.db.astra.datastax.com:29080/metadata. Check the cluster status in the cloud console. 
ERROR:cassandra.datastax.cloud:HTTP Error 401: Unauthorized
Traceback (most recent call last):
  File "/tmp/8dc9524939e911d/antenv/lib/python3.9/site-packages/cassandra/datastax/cloud/__init__.py", line 137, in read_metadata_info
    response = urlopen(url, context=config.ssl_context, timeout=timeout)
  File "/opt/python/3.9.19/lib/python3.9/urllib/request.py", line 214, in urlopen
    return opener.open(url, data, timeout)
  File "/opt/python/3.9.19/lib/python3.9/urllib/request.py", line 523, in open
    response = meth(req, response)
  File "/opt/python/3.9.19/lib/python3.9/urllib/request.py", line 632, in http_response
    response = self.parent.error(
  File "/opt/python/3.9.19/lib/python3.9/urllib/request.py", line 561, in error
    return self._call_chain(*args)
  File "/opt/python/3.9.19/lib/python3.9/urllib/request.py", line 494, in _call_chain
    result = func(*args)
  File "/opt/python/3.9.19/lib/python3.9/urllib/request.py", line 641, in http_error_default
    raise HTTPError(req.full_url, code, msg, hdrs, fp)
urllib.error.HTTPError: HTTP Error 401: Unauthorized
ERROR:app:Exception on /fetch [GET]
Traceback (most recent call last):
  File "/tmp/8dc9524939e911d/antenv/lib/python3.9/site-packages/cassandra/datastax/cloud/__init__.py", line 137, in read_metadata_info
    response = urlopen(url, context=config.ssl_context, timeout=timeout)
  File "/opt/python/3.9.19/lib/python3.9/urllib/request.py", line 214, in urlopen
    return opener.open(url, data, timeout)
  File "/opt/python/3.9.19/lib/python3.9/urllib/request.py", line 523, in open
    response = meth(req, response)
  File "/opt/python/3.9.19/lib/python3.9/urllib/request.py", line 632, in http_response
    response = self.parent.error(
  File "/opt/python/3.9.19/lib/python3.9/urllib/request.py", line 561, in error
    return self._call_chain(*args)
  File "/opt/python/3.9.19/lib/python3.9/urllib/request.py", line 494, in _call_chain
    result = func(*args)
  File "/opt/python/3.9.19/lib/python3.9/urllib/request.py", line 641, in http_error_default
    raise HTTPError(req.full_url, code, msg, hdrs, fp)
urllib.error.HTTPError: HTTP Error 401: Unauthorized

During handling of the above exception, another exception occurred:

Traceback (most recent call last):
  File "/tmp/8dc9524939e911d/antenv/lib/python3.9/site-packages/flask/app.py", line 1463, in wsgi_app
    response = self.full_dispatch_request()
  File "/tmp/8dc9524939e911d/antenv/lib/python3.9/site-packages/flask/app.py", line 872, in full_dispatch_request
    rv = self.handle_user_exception(e)
  File "/tmp/8dc9524939e911d/antenv/lib/python3.9/site-packages/flask/app.py", line 870, in full_dispatch_request
    rv = self.dispatch_request()
  File "/tmp/8dc9524939e911d/antenv/lib/python3.9/site-packages/flask/app.py", line 855, in dispatch_request
    return self.ensure_sync(self.view_functions[rule.endpoint])(**view_args)  # type: ignore[no-any-return]
  File "/tmp/8dc9524939e911d/app.py", line 66, in fetch
    all_entries = fetch_all_entries()
  File "/tmp/8dc9524939e911d/connect_database.py", line 60, in fetch_all_entries
    cluster, session = connect_to_cassandra()
  File "/tmp/8dc9524939e911d/connect_database.py", line 24, in connect_to_cassandra
    cluster = Cluster(cloud=cloud_config, auth_provider=auth_provider)
  File "cassandra/cluster.py", line 1172, in cassandra.cluster.Cluster.__init__
  File "/tmp/8dc9524939e911d/antenv/lib/python3.9/site-packages/cassandra/datastax/cloud/__init__.py", line 91, in get_cloud_config
    config = read_metadata_info(config, cloud_config)
  File "/tmp/8dc9524939e911d/antenv/lib/python3.9/site-packages/cassandra/datastax/cloud/__init__.py", line 140, in read_metadata_info
    raise DriverException("Unable to connect to the metadata service at %s. "
cassandra.DriverException: Unable to connect to the metadata service at https://74f3ea48-05df-4249-a12b-fac40645190d-us-east-1.db.astra.datastax.com:29080/metadata. Check the cluster status in the cloud console. 
ERROR:cassandra.datastax.cloud:HTTP Error 401: Unauthorized
Traceback (most recent call last):
  File "/tmp/8dc9524939e911d/antenv/lib/python3.9/site-packages/cassandra/datastax/cloud/__init__.py", line 137, in read_metadata_info
    response = urlopen(url, context=config.ssl_context, timeout=timeout)
  File "/opt/python/3.9.19/lib/python3.9/urllib/request.py", line 214, in urlopen
    return opener.open(url, data, timeout)
  File "/opt/python/3.9.19/lib/python3.9/urllib/request.py", line 523, in open
    response = meth(req, response)
  File "/opt/python/3.9.19/lib/python3.9/urllib/request.py", line 632, in http_response
    response = self.parent.error(
  File "/opt/python/3.9.19/lib/python3.9/urllib/request.py", line 561, in error
    return self._call_chain(*args)
  File "/opt/python/3.9.19/lib/python3.9/urllib/request.py", line 494, in _call_chain
    result = func(*args)
  File "/opt/python/3.9.19/lib/python3.9/urllib/request.py", line 641, in http_error_default
    raise HTTPError(req.full_url, code, msg, hdrs, fp)
urllib.error.HTTPError: HTTP Error 401: Unauthorized
ERROR:app:Exception on /fetch [GET]
Traceback (most recent call last):
  File "/tmp/8dc9524939e911d/antenv/lib/python3.9/site-packages/cassandra/datastax/cloud/__init__.py", line 137, in read_metadata_info
    response = urlopen(url, context=config.ssl_context, timeout=timeout)
  File "/opt/python/3.9.19/lib/python3.9/urllib/request.py", line 214, in urlopen
    return opener.open(url, data, timeout)
  File "/opt/python/3.9.19/lib/python3.9/urllib/request.py", line 523, in open
    response = meth(req, response)
  File "/opt/python/3.9.19/lib/python3.9/urllib/request.py", line 632, in http_response
    response = self.parent.error(
  File "/opt/python/3.9.19/lib/python3.9/urllib/request.py", line 561, in error
    return self._call_chain(*args)
  File "/opt/python/3.9.19/lib/python3.9/urllib/request.py", line 494, in _call_chain
    result = func(*args)
  File "/opt/python/3.9.19/lib/python3.9/urllib/request.py", line 641, in http_error_default
    raise HTTPError(req.full_url, code, msg, hdrs, fp)
urllib.error.HTTPError: HTTP Error 401: Unauthorized

During handling of the above exception, another exception occurred:

Traceback (most recent call last):
  File "/tmp/8dc9524939e911d/antenv/lib/python3.9/site-packages/flask/app.py", line 1463, in wsgi_app
    response = self.full_dispatch_request()
  File "/tmp/8dc9524939e911d/antenv/lib/python3.9/site-packages/flask/app.py", line 872, in full_dispatch_request
    rv = self.handle_user_exception(e)
  File "/tmp/8dc9524939e911d/antenv/lib/python3.9/site-packages/flask/app.py", line 870, in full_dispatch_request
    rv = self.dispatch_request()
  File "/tmp/8dc9524939e911d/antenv/lib/python3.9/site-packages/flask/app.py", line 855, in dispatch_request
    return self.ensure_sync(self.view_functions[rule.endpoint])(**view_args)  # type: ignore[no-any-return]
  File "/tmp/8dc9524939e911d/app.py", line 66, in fetch
    all_entries = fetch_all_entries()
  File "/tmp/8dc9524939e911d/connect_database.py", line 60, in fetch_all_entries
    cluster, session = connect_to_cassandra()
  File "/tmp/8dc9524939e911d/connect_database.py", line 24, in connect_to_cassandra
    cluster = Cluster(cloud=cloud_config, auth_provider=auth_provider)
  File "cassandra/cluster.py", line 1172, in cassandra.cluster.Cluster.__init__
  File "/tmp/8dc9524939e911d/antenv/lib/python3.9/site-packages/cassandra/datastax/cloud/__init__.py", line 91, in get_cloud_config
    config = read_metadata_info(config, cloud_config)
  File "/tmp/8dc9524939e911d/antenv/lib/python3.9/site-packages/cassandra/datastax/cloud/__init__.py", line 140, in read_metadata_info
    raise DriverException("Unable to connect to the metadata service at %s. "
cassandra.DriverException: Unable to connect to the metadata service at https://74f3ea48-05df-4249-a12b-fac40645190d-us-east-1.db.astra.datastax.com:29080/metadata. Check the cluster status in the cloud console. 
ERROR:cassandra.datastax.cloud:HTTP Error 401: Unauthorized
Traceback (most recent call last):
  File "/tmp/8dc9524939e911d/antenv/lib/python3.9/site-packages/cassandra/datastax/cloud/__init__.py", line 137, in read_metadata_info
    response = urlopen(url, context=config.ssl_context, timeout=timeout)
  File "/opt/python/3.9.19/lib/python3.9/urllib/request.py", line 214, in urlopen
    return opener.open(url, data, timeout)
  File "/opt/python/3.9.19/lib/python3.9/urllib/request.py", line 523, in open
    response = meth(req, response)
  File "/opt/python/3.9.19/lib/python3.9/urllib/request.py", line 632, in http_response
    response = self.parent.error(
  File "/opt/python/3.9.19/lib/python3.9/urllib/request.py", line 561, in error
    return self._call_chain(*args)
  File "/opt/python/3.9.19/lib/python3.9/urllib/request.py", line 494, in _call_chain
    result = func(*args)
  File "/opt/python/3.9.19/lib/python3.9/urllib/request.py", line 641, in http_error_default
    raise HTTPError(req.full_url, code, msg, hdrs, fp)
urllib.error.HTTPError: HTTP Error 401: Unauthorized
ERROR:cassandra.datastax.cloud:HTTP Error 401: Unauthorized
Traceback (most recent call last):
  File "/tmp/8dc9524939e911d/antenv/lib/python3.9/site-packages/cassandra/datastax/cloud/__init__.py", line 137, in read_metadata_info
    response = urlopen(url, context=config.ssl_context, timeout=timeout)
  File "/opt/python/3.9.19/lib/python3.9/urllib/request.py", line 214, in urlopen
    return opener.open(url, data, timeout)
  File "/opt/python/3.9.19/lib/python3.9/urllib/request.py", line 523, in open
    response = meth(req, response)
  File "/opt/python/3.9.19/lib/python3.9/urllib/request.py", line 632, in http_response
    response = self.parent.error(
  File "/opt/python/3.9.19/lib/python3.9/urllib/request.py", line 561, in error
    return self._call_chain(*args)
  File "/opt/python/3.9.19/lib/python3.9/urllib/request.py", line 494, in _call_chain
    result = func(*args)
  File "/opt/python/3.9.19/lib/python3.9/urllib/request.py", line 641, in http_error_default
    raise HTTPError(req.full_url, code, msg, hdrs, fp)
urllib.error.HTTPError: HTTP Error 401: Unauthorized
ERROR:cassandra.datastax.cloud:HTTP Error 401: Unauthorized
Traceback (most recent call last):
  File "/tmp/8dc9524939e911d/antenv/lib/python3.9/site-packages/cassandra/datastax/cloud/__init__.py", line 137, in read_metadata_info
    response = urlopen(url, context=config.ssl_context, timeout=timeout)
  File "/opt/python/3.9.19/lib/python3.9/urllib/request.py", line 214, in urlopen
    return opener.open(url, data, timeout)
  File "/opt/python/3.9.19/lib/python3.9/urllib/request.py", line 523, in open
    response = meth(req, response)
  File "/opt/python/3.9.19/lib/python3.9/urllib/request.py", line 632, in http_response
    response = self.parent.error(
  File "/opt/python/3.9.19/lib/python3.9/urllib/request.py", line 561, in error
    return self._call_chain(*args)
  File "/opt/python/3.9.19/lib/python3.9/urllib/request.py", line 494, in _call_chain
    result = func(*args)
  File "/opt/python/3.9.19/lib/python3.9/urllib/request.py", line 641, in http_error_default
    raise HTTPError(req.full_url, code, msg, hdrs, fp)
urllib.error.HTTPError: HTTP Error 401: Unauthorized
ERROR:cassandra.datastax.cloud:HTTP Error 401: Unauthorized
Traceback (most recent call last):
  File "/tmp/8dc9524939e911d/antenv/lib/python3.9/site-packages/cassandra/datastax/cloud/__init__.py", line 137, in read_metadata_info
    response = urlopen(url, context=config.ssl_context, timeout=timeout)
  File "/opt/python/3.9.19/lib/python3.9/urllib/request.py", line 214, in urlopen
    return opener.open(url, data, timeout)
  File "/opt/python/3.9.19/lib/python3.9/urllib/request.py", line 523, in open
    response = meth(req, response)
  File "/opt/python/3.9.19/lib/python3.9/urllib/request.py", line 632, in http_response
    response = self.parent.error(
  File "/opt/python/3.9.19/lib/python3.9/urllib/request.py", line 561, in error
    return self._call_chain(*args)
  File "/opt/python/3.9.19/lib/python3.9/urllib/request.py", line 494, in _call_chain
    result = func(*args)
  File "/opt/python/3.9.19/lib/python3.9/urllib/request.py", line 641, in http_error_default
    raise HTTPError(req.full_url, code, msg, hdrs, fp)
urllib.error.HTTPError: HTTP Error 401: Unauthorized
INFO:app:*****************Prediction opening *************************
ERROR:cassandra.datastax.cloud:HTTP Error 401: Unauthorized
Traceback (most recent call last):
  File "/tmp/8dc9524939e911d/antenv/lib/python3.9/site-packages/cassandra/datastax/cloud/__init__.py", line 137, in read_metadata_info
    response = urlopen(url, context=config.ssl_context, timeout=timeout)
  File "/opt/python/3.9.19/lib/python3.9/urllib/request.py", line 214, in urlopen
    return opener.open(url, data, timeout)
  File "/opt/python/3.9.19/lib/python3.9/urllib/request.py", line 523, in open
    response = meth(req, response)
  File "/opt/python/3.9.19/lib/python3.9/urllib/request.py", line 632, in http_response
    response = self.parent.error(
  File "/opt/python/3.9.19/lib/python3.9/urllib/request.py", line 561, in error
    return self._call_chain(*args)
  File "/opt/python/3.9.19/lib/python3.9/urllib/request.py", line 494, in _call_chain
    result = func(*args)
  File "/opt/python/3.9.19/lib/python3.9/urllib/request.py", line 641, in http_error_default
    raise HTTPError(req.full_url, code, msg, hdrs, fp)
urllib.error.HTTPError: HTTP Error 401: Unauthorized
ERROR:cassandra.datastax.cloud:HTTP Error 401: Unauthorized
Traceback (most recent call last):
  File "/tmp/8dc9524939e911d/antenv/lib/python3.9/site-packages/cassandra/datastax/cloud/__init__.py", line 137, in read_metadata_info
    response = urlopen(url, context=config.ssl_context, timeout=timeout)
  File "/opt/python/3.9.19/lib/python3.9/urllib/request.py", line 214, in urlopen
    return opener.open(url, data, timeout)
  File "/opt/python/3.9.19/lib/python3.9/urllib/request.py", line 523, in open
    response = meth(req, response)
  File "/opt/python/3.9.19/lib/python3.9/urllib/request.py", line 632, in http_response
    response = self.parent.error(
  File "/opt/python/3.9.19/lib/python3.9/urllib/request.py", line 561, in error
    return self._call_chain(*args)
  File "/opt/python/3.9.19/lib/python3.9/urllib/request.py", line 494, in _call_chain
    result = func(*args)
  File "/opt/python/3.9.19/lib/python3.9/urllib/request.py", line 641, in http_error_default
    raise HTTPError(req.full_url, code, msg, hdrs, fp)
urllib.error.HTTPError: HTTP Error 401: Unauthorized
ERROR:cassandra.datastax.cloud:HTTP Error 401: Unauthorized
Traceback (most recent call last):
  File "/tmp/8dc9524939e911d/antenv/lib/python3.9/site-packages/cassandra/datastax/cloud/__init__.py", line 137, in read_metadata_info
    response = urlopen(url, context=config.ssl_context, timeout=timeout)
  File "/opt/python/3.9.19/lib/python3.9/urllib/request.py", line 214, in urlopen
    return opener.open(url, data, timeout)
  File "/opt/python/3.9.19/lib/python3.9/urllib/request.py", line 523, in open
    response = meth(req, response)
  File "/opt/python/3.9.19/lib/python3.9/urllib/request.py", line 632, in http_response
    response = self.parent.error(
  File "/opt/python/3.9.19/lib/python3.9/urllib/request.py", line 561, in error
    return self._call_chain(*args)
  File "/opt/python/3.9.19/lib/python3.9/urllib/request.py", line 494, in _call_chain
    result = func(*args)
  File "/opt/python/3.9.19/lib/python3.9/urllib/request.py", line 641, in http_error_default
    raise HTTPError(req.full_url, code, msg, hdrs, fp)
urllib.error.HTTPError: HTTP Error 401: Unauthorized
ERROR:cassandra.datastax.cloud:HTTP Error 401: Unauthorized
Traceback (most recent call last):
  File "/tmp/8dc9524939e911d/antenv/lib/python3.9/site-packages/cassandra/datastax/cloud/__init__.py", line 137, in read_metadata_info
    response = urlopen(url, context=config.ssl_context, timeout=timeout)
  File "/opt/python/3.9.19/lib/python3.9/urllib/request.py", line 214, in urlopen
    return opener.open(url, data, timeout)
  File "/opt/python/3.9.19/lib/python3.9/urllib/request.py", line 523, in open
    response = meth(req, response)
  File "/opt/python/3.9.19/lib/python3.9/urllib/request.py", line 632, in http_response
    response = self.parent.error(
  File "/opt/python/3.9.19/lib/python3.9/urllib/request.py", line 561, in error
    return self._call_chain(*args)
  File "/opt/python/3.9.19/lib/python3.9/urllib/request.py", line 494, in _call_chain
    result = func(*args)
  File "/opt/python/3.9.19/lib/python3.9/urllib/request.py", line 641, in http_error_default
    raise HTTPError(req.full_url, code, msg, hdrs, fp)
urllib.error.HTTPError: HTTP Error 401: Unauthorized
ERROR:cassandra.datastax.cloud:HTTP Error 401: Unauthorized
Traceback (most recent call last):
  File "/tmp/8dc9524939e911d/antenv/lib/python3.9/site-packages/cassandra/datastax/cloud/__init__.py", line 137, in read_metadata_info
    response = urlopen(url, context=config.ssl_context, timeout=timeout)
  File "/opt/python/3.9.19/lib/python3.9/urllib/request.py", line 214, in urlopen
    return opener.open(url, data, timeout)
  File "/opt/python/3.9.19/lib/python3.9/urllib/request.py", line 523, in open
    response = meth(req, response)
  File "/opt/python/3.9.19/lib/python3.9/urllib/request.py", line 632, in http_response
    response = self.parent.error(
  File "/opt/python/3.9.19/lib/python3.9/urllib/request.py", line 561, in error
    return self._call_chain(*args)
  File "/opt/python/3.9.19/lib/python3.9/urllib/request.py", line 494, in _call_chain
    result = func(*args)
  File "/opt/python/3.9.19/lib/python3.9/urllib/request.py", line 641, in http_error_default
    raise HTTPError(req.full_url, code, msg, hdrs, fp)
urllib.error.HTTPError: HTTP Error 401: Unauthorized
ERROR:cassandra.datastax.cloud:HTTP Error 401: Unauthorized
Traceback (most recent call last):
  File "/tmp/8dc9524939e911d/antenv/lib/python3.9/site-packages/cassandra/datastax/cloud/__init__.py", line 137, in read_metadata_info
    response = urlopen(url, context=config.ssl_context, timeout=timeout)
  File "/opt/python/3.9.19/lib/python3.9/urllib/request.py", line 214, in urlopen
    return opener.open(url, data, timeout)
  File "/opt/python/3.9.19/lib/python3.9/urllib/request.py", line 523, in open
    response = meth(req, response)
  File "/opt/python/3.9.19/lib/python3.9/urllib/request.py", line 632, in http_response
    response = self.parent.error(
  File "/opt/python/3.9.19/lib/python3.9/urllib/request.py", line 561, in error
    return self._call_chain(*args)
  File "/opt/python/3.9.19/lib/python3.9/urllib/request.py", line 494, in _call_chain
    result = func(*args)
  File "/opt/python/3.9.19/lib/python3.9/urllib/request.py", line 641, in http_error_default
    raise HTTPError(req.full_url, code, msg, hdrs, fp)
urllib.error.HTTPError: HTTP Error 401: Unauthorized
INFO:app:*****************Prediction opening *************************
ERROR:cassandra.datastax.cloud:HTTP Error 401: Unauthorized
Traceback (most recent call last):
  File "/tmp/8dc9524939e911d/antenv/lib/python3.9/site-packages/cassandra/datastax/cloud/__init__.py", line 137, in read_metadata_info
    response = urlopen(url, context=config.ssl_context, timeout=timeout)
  File "/opt/python/3.9.19/lib/python3.9/urllib/request.py", line 214, in urlopen
    return opener.open(url, data, timeout)
  File "/opt/python/3.9.19/lib/python3.9/urllib/request.py", line 523, in open
    response = meth(req, response)
  File "/opt/python/3.9.19/lib/python3.9/urllib/request.py", line 632, in http_response
    response = self.parent.error(
  File "/opt/python/3.9.19/lib/python3.9/urllib/request.py", line 561, in error
    return self._call_chain(*args)
  File "/opt/python/3.9.19/lib/python3.9/urllib/request.py", line 494, in _call_chain
    result = func(*args)
  File "/opt/python/3.9.19/lib/python3.9/urllib/request.py", line 641, in http_error_default
    raise HTTPError(req.full_url, code, msg, hdrs, fp)
urllib.error.HTTPError: HTTP Error 401: Unauthorized
ERROR:cassandra.datastax.cloud:HTTP Error 401: Unauthorized
Traceback (most recent call last):
  File "/tmp/8dc9524939e911d/antenv/lib/python3.9/site-packages/cassandra/datastax/cloud/__init__.py", line 137, in read_metadata_info
    response = urlopen(url, context=config.ssl_context, timeout=timeout)
  File "/opt/python/3.9.19/lib/python3.9/urllib/request.py", line 214, in urlopen
    return opener.open(url, data, timeout)
  File "/opt/python/3.9.19/lib/python3.9/urllib/request.py", line 523, in open
    response = meth(req, response)
  File "/opt/python/3.9.19/lib/python3.9/urllib/request.py", line 632, in http_response
    response = self.parent.error(
  File "/opt/python/3.9.19/lib/python3.9/urllib/request.py", line 561, in error
    return self._call_chain(*args)
  File "/opt/python/3.9.19/lib/python3.9/urllib/request.py", line 494, in _call_chain
    result = func(*args)
  File "/opt/python/3.9.19/lib/python3.9/urllib/request.py", line 641, in http_error_default
    raise HTTPError(req.full_url, code, msg, hdrs, fp)
urllib.error.HTTPError: HTTP Error 401: Unauthorized
INFO:app:*****************Prediction opening *************************
INFO:app:*****************Prediction opening *************************
ERROR:cassandra.datastax.cloud:HTTP Error 401: Unauthorized
Traceback (most recent call last):
  File "/tmp/8dc9524939e911d/antenv/lib/python3.9/site-packages/cassandra/datastax/cloud/__init__.py", line 137, in read_metadata_info
    response = urlopen(url, context=config.ssl_context, timeout=timeout)
  File "/opt/python/3.9.19/lib/python3.9/urllib/request.py", line 214, in urlopen
    return opener.open(url, data, timeout)
  File "/opt/python/3.9.19/lib/python3.9/urllib/request.py", line 523, in open
    response = meth(req, response)
  File "/opt/python/3.9.19/lib/python3.9/urllib/request.py", line 632, in http_response
    response = self.parent.error(
  File "/opt/python/3.9.19/lib/python3.9/urllib/request.py", line 561, in error
    return self._call_chain(*args)
  File "/opt/python/3.9.19/lib/python3.9/urllib/request.py", line 494, in _call_chain
    result = func(*args)
  File "/opt/python/3.9.19/lib/python3.9/urllib/request.py", line 641, in http_error_default
    raise HTTPError(req.full_url, code, msg, hdrs, fp)
urllib.error.HTTPError: HTTP Error 401: Unauthorized
ERROR:app:Exception on / [HEAD]
Traceback (most recent call last):
  File "/tmp/8dc9524939e911d/antenv/lib/python3.9/site-packages/flask/app.py", line 1463, in wsgi_app
    response = self.full_dispatch_request()
  File "/tmp/8dc9524939e911d/antenv/lib/python3.9/site-packages/flask/app.py", line 873, in full_dispatch_request
    return self.finalize_request(rv)
  File "/tmp/8dc9524939e911d/antenv/lib/python3.9/site-packages/flask/app.py", line 892, in finalize_request
    response = self.make_response(rv)
  File "/tmp/8dc9524939e911d/antenv/lib/python3.9/site-packages/flask/app.py", line 1164, in make_response
    raise TypeError(
TypeError: The view function for 'predictui' did not return a valid response. The function either returned None or ended without a return statement.
ERROR:app:Exception on / [HEAD]
Traceback (most recent call last):
  File "/tmp/8dc9524939e911d/antenv/lib/python3.9/site-packages/flask/app.py", line 1463, in wsgi_app
    response = self.full_dispatch_request()
  File "/tmp/8dc9524939e911d/antenv/lib/python3.9/site-packages/flask/app.py", line 873, in full_dispatch_request
    return self.finalize_request(rv)
  File "/tmp/8dc9524939e911d/antenv/lib/python3.9/site-packages/flask/app.py", line 892, in finalize_request
    response = self.make_response(rv)
  File "/tmp/8dc9524939e911d/antenv/lib/python3.9/site-packages/flask/app.py", line 1164, in make_response
    raise TypeError(
TypeError: The view function for 'predictui' did not return a valid response. The function either returned None or ended without a return statement.
INFO:app:*****************Prediction opening *************************
INFO:app:*****************Prediction opening *************************
ERROR:cassandra.datastax.cloud:HTTP Error 401: Unauthorized
Traceback (most recent call last):
  File "/tmp/8dc9524939e911d/antenv/lib/python3.9/site-packages/cassandra/datastax/cloud/__init__.py", line 137, in read_metadata_info
    response = urlopen(url, context=config.ssl_context, timeout=timeout)
  File "/opt/python/3.9.19/lib/python3.9/urllib/request.py", line 214, in urlopen
    return opener.open(url, data, timeout)
  File "/opt/python/3.9.19/lib/python3.9/urllib/request.py", line 523, in open
    response = meth(req, response)
  File "/opt/python/3.9.19/lib/python3.9/urllib/request.py", line 632, in http_response
    response = self.parent.error(
  File "/opt/python/3.9.19/lib/python3.9/urllib/request.py", line 561, in error
    return self._call_chain(*args)
  File "/opt/python/3.9.19/lib/python3.9/urllib/request.py", line 494, in _call_chain
    result = func(*args)
  File "/opt/python/3.9.19/lib/python3.9/urllib/request.py", line 641, in http_error_default
    raise HTTPError(req.full_url, code, msg, hdrs, fp)
urllib.error.HTTPError: HTTP Error 401: Unauthorized
INFO:app:*****************Prediction opening *************************
INFO:app:*****************Prediction for URL started *************************
INFO:app:time_response 0.135492
INFO:app:domain_spf 1
INFO:app:asn_ip 1
INFO:app:time_domain_activation 6111
INFO:app:time_domain_expiration 0
INFO:app:qty_ip_resolved 4
INFO:app:qty_nameservers 4
INFO:app:qty_mx_servers 2
INFO:app:ttl_hostname 1
INFO:app:tls_ssl_certificate 1
INFO:app:qty_redirects 1
INFO:app:url_google_index 1
INFO:app:domain_google_index 0
INFO:app:url_shortened 0
INFO:app:Domain: youtu.be
INFO:app:URL: https://youtu.be/3qHkcs3kG44
INFO:app:*****************Prediction for https://youtu.be/3qHkcs3kG44 is Prediction says safe browsing URL *************************
ERROR:cassandra.datastax.cloud:HTTP Error 401: Unauthorized
Traceback (most recent call last):
  File "/tmp/8dc9524939e911d/antenv/lib/python3.9/site-packages/cassandra/datastax/cloud/__init__.py", line 137, in read_metadata_info
    response = urlopen(url, context=config.ssl_context, timeout=timeout)
  File "/opt/python/3.9.19/lib/python3.9/urllib/request.py", line 214, in urlopen
    return opener.open(url, data, timeout)
  File "/opt/python/3.9.19/lib/python3.9/urllib/request.py", line 523, in open
    response = meth(req, response)
  File "/opt/python/3.9.19/lib/python3.9/urllib/request.py", line 632, in http_response
    response = self.parent.error(
  File "/opt/python/3.9.19/lib/python3.9/urllib/request.py", line 561, in error
    return self._call_chain(*args)
  File "/opt/python/3.9.19/lib/python3.9/urllib/request.py", line 494, in _call_chain
    result = func(*args)
  File "/opt/python/3.9.19/lib/python3.9/urllib/request.py", line 641, in http_error_default
    raise HTTPError(req.full_url, code, msg, hdrs, fp)
urllib.error.HTTPError: HTTP Error 401: Unauthorized
ERROR:app:*****************Database is not working*************************
INFO:app:*****************Prediction opening *************************
INFO:app:*****************Prediction opening *************************
ERROR:cassandra.datastax.cloud:HTTP Error 401: Unauthorized
Traceback (most recent call last):
  File "/tmp/8dc9524939e911d/antenv/lib/python3.9/site-packages/cassandra/datastax/cloud/__init__.py", line 137, in read_metadata_info
    response = urlopen(url, context=config.ssl_context, timeout=timeout)
  File "/opt/python/3.9.19/lib/python3.9/urllib/request.py", line 214, in urlopen
    return opener.open(url, data, timeout)
  File "/opt/python/3.9.19/lib/python3.9/urllib/request.py", line 523, in open
    response = meth(req, response)
  File "/opt/python/3.9.19/lib/python3.9/urllib/request.py", line 632, in http_response
    response = self.parent.error(
  File "/opt/python/3.9.19/lib/python3.9/urllib/request.py", line 561, in error
    return self._call_chain(*args)
  File "/opt/python/3.9.19/lib/python3.9/urllib/request.py", line 494, in _call_chain
    result = func(*args)
  File "/opt/python/3.9.19/lib/python3.9/urllib/request.py", line 641, in http_error_default
    raise HTTPError(req.full_url, code, msg, hdrs, fp)
urllib.error.HTTPError: HTTP Error 401: Unauthorized
INFO:app:*****************Prediction opening *************************
ERROR:cassandra.datastax.cloud:HTTP Error 401: Unauthorized
Traceback (most recent call last):
  File "/tmp/8dc9524939e911d/antenv/lib/python3.9/site-packages/cassandra/datastax/cloud/__init__.py", line 137, in read_metadata_info
    response = urlopen(url, context=config.ssl_context, timeout=timeout)
  File "/opt/python/3.9.19/lib/python3.9/urllib/request.py", line 214, in urlopen
    return opener.open(url, data, timeout)
  File "/opt/python/3.9.19/lib/python3.9/urllib/request.py", line 523, in open
    response = meth(req, response)
  File "/opt/python/3.9.19/lib/python3.9/urllib/request.py", line 632, in http_response
    response = self.parent.error(
  File "/opt/python/3.9.19/lib/python3.9/urllib/request.py", line 561, in error
    return self._call_chain(*args)
  File "/opt/python/3.9.19/lib/python3.9/urllib/request.py", line 494, in _call_chain
    result = func(*args)
  File "/opt/python/3.9.19/lib/python3.9/urllib/request.py", line 641, in http_error_default
    raise HTTPError(req.full_url, code, msg, hdrs, fp)
urllib.error.HTTPError: HTTP Error 401: Unauthorized
INFO:app:*****************Prediction opening *************************
INFO:app:*****************Prediction opening *************************
INFO:app:*****************Prediction opening *************************
ERROR:cassandra.datastax.cloud:HTTP Error 401: Unauthorized
Traceback (most recent call last):
  File "/tmp/8dc9524939e911d/antenv/lib/python3.9/site-packages/cassandra/datastax/cloud/__init__.py", line 137, in read_metadata_info
    response = urlopen(url, context=config.ssl_context, timeout=timeout)
  File "/opt/python/3.9.19/lib/python3.9/urllib/request.py", line 214, in urlopen
    return opener.open(url, data, timeout)
  File "/opt/python/3.9.19/lib/python3.9/urllib/request.py", line 523, in open
    response = meth(req, response)
  File "/opt/python/3.9.19/lib/python3.9/urllib/request.py", line 632, in http_response
    response = self.parent.error(
  File "/opt/python/3.9.19/lib/python3.9/urllib/request.py", line 561, in error
    return self._call_chain(*args)
  File "/opt/python/3.9.19/lib/python3.9/urllib/request.py", line 494, in _call_chain
    result = func(*args)
  File "/opt/python/3.9.19/lib/python3.9/urllib/request.py", line 641, in http_error_default
    raise HTTPError(req.full_url, code, msg, hdrs, fp)
urllib.error.HTTPError: HTTP Error 401: Unauthorized
INFO:app:*****************Prediction opening *************************
INFO:app:*****************Prediction opening *************************
